Workbook

Sheet Dados
A8: Status parcial transmissão de dados QualifarSUS
A9: Ciclo de referência: 1º de 2026
A10: Data de extração dos dados 30/12/2025
A13: Cód. IBGE | B13: Município | C13: UF | D13: Data habilitação QualifarSUS | E13: 45962 | G13: 45992 | I13: 46023
E14: Saída | F14: Posição de estoque | G14: Saída | H14: Posição de estoque | I14: Saída | J14: Posição de estoque
A15: 120001 | B15: ACRELÂNDIA | C15: AC | D15: 2018-12-11 | E15: =VLOOKUP(A15,Planilha1!A:Y,20,FALSE) -> Não | F15: =VLOOKUP(A15,Planilha1!A:Y,21,FALSE) -> Sim | G15: =VLOOKUP(A15,Planilha1!A:Y,22,FALSE) -> Não | H15: =VLOOKUP(A15,Planilha1!A:Y,23,FALSE) -> Sim | I15: =VLOOKUP(A15,Planilha1!A:Y,24,FALSE) -> Não | J15: =VLOOKUP(A15,Planilha1!A:Y,25,FALSE) -> Não
A16: 120005 | B16: ASSIS BRASIL | C16: AC | D16: 2012-06-13 | E16: =VLOOKUP(A16,Planilha1!A:Y,20,FALSE) -> Sim | F16: =VLOOKUP(A16,Planilha1!A:Y,21,FALSE) -> Sim | G16: =VLOOKUP(A16,Planilha1!A:Y,22,FALSE) -> Sim | H16: =VLOOKUP(A16,Planilha1!A:Y,23,FALSE) -> Sim | I16: =VLOOKUP(A16,Planilha1!A:Y,24,FALSE) -> Não | J16: =VLOOKUP(A16,Planilha1!A:Y,25,FALSE) -> Não
A17: 120010 | B17: BRASILÉIA | C17: AC | D17: 2017-12-30 | E17: =VLOOKUP(A17,Planilha1!A:Y,20,FALSE) -> Sim | F17: =VLOOKUP(A17,Planilha1!A:Y,21,FALSE) -> Sim | G17: =VLOOKUP(A17,Planilha1!A:Y,22,FALSE) -> Sim | H17: =VLOOKUP(A17,Planilha1!A:Y,23,FALSE) -> Sim | I17: =VLOOKUP(A17,Planilha1!A:Y,24,FALSE) -> Não | J17: =VLOOKUP(A17,Planilha1!A:Y,25,FALSE) -> Não
A18: 120013 | B18: BUJARI | C18: AC | D18: 2014-09-23 | E18: =VLOOKUP(A18,Planilha1!A:Y,20,FALSE) -> Sim | F18: =VLOOKUP(A18,Planilha1!A:Y,21,FALSE) -> Sim | G18: =VLOOKUP(A18,Planilha1!A:Y,22,FALSE) -> Sim | H18: =VLOOKUP(A18,Planilha1!A:Y,23,FALSE) -> Sim | I18: =VLOOKUP(A18,Planilha1!A:Y,24,FALSE) -> Não | J18: =VLOOKUP(A18,Planilha1!A:Y,25,FALSE) -> Não
A19: 120017 | B19: CAPIXABA | C19: AC | D19: 2023-12-20 | E19: =VLOOKUP(A19,Planilha1!A:Y,20,FALSE) -> Não | F19: =VLOOKUP(A19,Planilha1!A:Y,21,FALSE) -> Sim | G19: =VLOOKUP(A19,Planilha1!A:Y,22,FALSE) -> Não | H19: =VLOOKUP(A19,Planilha1!A:Y,23,FALSE) -> Sim | I19: =VLOOKUP(A19,Planilha1!A:Y,24,FALSE) -> Não | J19: =VLOOKUP(A19,Planilha1!A:Y,25,FALSE) -> Não
A20: 120025 | B20: EPITACIOLÂNDIA | C20: AC | D20: 2023-12-20 | E20: =VLOOKUP(A20,Planilha1!A:Y,20,FALSE) -> Sim | F20: =VLOOKUP(A20,Planilha1!A:Y,21,FALSE) -> Sim | G20: =VLOOKUP(A20,Planilha1!A:Y,22,FALSE) -> Sim | H20: =VLOOKUP(A20,Planilha1!A:Y,23,FALSE) -> Sim | I20: =VLOOKUP(A20,Planilha1!A:Y,24,FALSE) -> Não | J20: =VLOOKUP(A20,Planilha1!A:Y,25,FALSE) -> Não
A21: 120030 | B21: FEIJÓ | C21: AC | D21: 2014-09-23 | E21: =VLOOKUP(A21,Planilha1!A:Y,20,FALSE) -> Não | F21: =VLOOKUP(A21,Planilha1!A:Y,21,FALSE) -> Não | G21: =VLOOKUP(A21,Planilha1!A:Y,22,FALSE) -> Não | H21: =VLOOKUP(A21,Planilha1!A:Y,23,FALSE) -> Não | I21: =VLOOKUP(A21,Planilha1!A:Y,24,FALSE) -> Não | J21: =VLOOKUP(A21,Planilha1!A:Y,25,FALSE) -> Não
A22: 120032 | B22: JORDÃO | C22: AC | D22: 2014-09-23 | E22: =VLOOKUP(A22,Planilha1!A:Y,20,FALSE) -> Não | F22: =VLOOKUP(A22,Planilha1!A:Y,21,FALSE) -> Não | G22: =VLOOKUP(A22,Planilha1!A:Y,22,FALSE) -> Não | H22: =VLOOKUP(A22,Planilha1!A:Y,23,FALSE) -> Não | I22: =VLOOKUP(A22,Planilha1!A:Y,24,FALSE) -> Não | J22: =VLOOKUP(A22,Planilha1!A:Y,25,FALSE) -> Não
A23: 120033 | B23: MÂNCIO LIMA | C23: AC | D23: 2012-06-13 | E23: =VLOOKUP(A23,Planilha1!A:Y,20,FALSE) -> Sim | F23: =VLOOKUP(A23,Planilha1!A:Y,21,FALSE) -> Sim | G23: =VLOOKUP(A23,Planilha1!A:Y,22,FALSE) -> Sim | H23: =VLOOKUP(A23,Planilha1!A:Y,23,FALSE) -> Sim | I23: =VLOOKUP(A23,Planilha1!A:Y,24,FALSE) -> Não | J23: =VLOOKUP(A23,Planilha1!A:Y,25,FALSE) -> Não
A24: 120034 | B24: MANOEL URBANO | C24: AC | D24: 2013-05-27 | E24: =VLOOKUP(A24,Planilha1!A:Y,20,FALSE) -> Não | F24: =VLOOKUP(A24,Planilha1!A:Y,21,FALSE) -> Sim | G24: =VLOOKUP(A24,Planilha1!A:Y,22,FALSE) -> Não | H24: =VLOOKUP(A24,Planilha1!A:Y,23,FALSE) -> Sim | I24: =VLOOKUP(A24,Planilha1!A:Y,24,FALSE) -> Não | J24: =VLOOKUP(A24,Planilha1!A:Y,25,FALSE) -> Não
A25: 120035 | B25: MARECHAL THAUMATURGO | C25: AC | D25: 2019-12-19 | E25: =VLOOKUP(A25,Planilha1!A:Y,20,FALSE) -> Sim | F25: =VLOOKUP(A25,Planilha1!A:Y,21,FALSE) -> Sim | G25: =VLOOKUP(A25,Planilha1!A:Y,22,FALSE) -> Sim | H25: =VLOOKUP(A25,Planilha1!A:Y,23,FALSE) -> Sim | I25: =VLOOKUP(A25,Planilha1!A:Y,24,FALSE) -> Não | J25: =VLOOKUP(A25,Planilha1!A:Y,25,FALSE) -> Não
A26: 120039 | B26: PORTO WALTER | C26: AC | D26: 2013-05-27 | E26: =VLOOKUP(A26,Planilha1!A:Y,20,FALSE) -> Sim | F26: =VLOOKUP(A26,Planilha1!A:Y,21,FALSE) -> Sim | G26: =VLOOKUP(A26,Planilha1!A:Y,22,FALSE) -> Sim | H26: =VLOOKUP(A26,Planilha1!A:Y,23,FALSE) -> Sim | I26: =VLOOKUP(A26,Planilha1!A:Y,24,FALSE) -> Não | J26: =VLOOKUP(A26,Planilha1!A:Y,25,FALSE) -> Não
... A4572: 172210 | B4572: XAMBIOÁ | C4572: TO | D4572: 2023-12-20 | E4572: =VLOOKUP(A4572,Planilha1!A:Y,20,FALSE) -> Sim | F4572: =VLOOKUP(A4572,Planilha1!A:Y,21,FALSE) -> Sim | G4572: =VLOOKUP(A4572,Planilha1!A:Y,22,FALSE) -> Sim | H4572: =VLOOKUP(A4572,Planilha1!A:Y,23,FALSE) -> Sim | I4572: =VLOOKUP(A4572,Planilha1!A:Y,24,FALSE) -> Não | J4572: =VLOOKUP(A4572,Planilha1!A:Y,25,FALSE) -> Não

Sheet Planilha1
A1: 1 | B1: 2 | C1: 3 | D1: 4 | E1: 5 | F1: 6 | G1: 7 | H1: 8 | I1: 9 | J1: 10 | K1: 11 | L1: 12 | M1: 13 | N1: 14 | O1: 15 | P1: 16 | Q1: 17 | R1: 18 | S1: 19 | T1: 20 | U1: 21 | V1: 22 | W1: 23 | X1: 24 | Y1: 25
B2: Hórus | H2: Web Service | N2: SOA Bnafar | T2: Final
B3: Mês 1 | D3: Mês 2 | F3: Mês 3 | H3: Mês 1 | J3: Mês 2 | L3: Mês 3 | N3: Mês 1 | P3: Mês 2 | R3: Mês 3 | T3: Mês 1 | V3: Mês 2 | X3: Mês 3
B4: Saida | C4: Posição de estoque | D4: Saida | E4: Posição de estoque | F4: Saida | G4: Posição de estoque | H4: Saida | I4: Posição de estoque | J4: Saida | K4: Posição de estoque | L4: Saida | M4: Posição de estoque | N4: Saida | O4: Posição de estoque | P4: Saida | Q4: Posição de estoque | R4: Saida | S4: Posição de estoque | T4: Saida | U4: Posição de estoque | V4: Saida | W4: Posição de estoque | X4: Saida | Y4: Posição de estoque
A5: 120001 | B5: =IFERROR(VLOOKUP(A5,[1]Monitoramento_Base_somente_Said!$A:$J,5,FALSE),0) -> 0 | C5: =IFERROR(VLOOKUP(A5,[1]Monitoramento_Base_somente_Said!$A:$J,6,FALSE),0) -> 22079078 | D5: =IFERROR(VLOOKUP(A5,[1]Monitoramento_Base_somente_Said!$A:$J,7,FALSE),0) -> 0 | E5: =IFERROR(VLOOKUP(A5,[1]Monitoramento_Base_somente_Said!$A:$J,8,FALSE),0) -> 21811197 | F5: =IFERROR(VLOOKUP(A5,[1]Monitoramento_Base_somente_Said!$A:$J,9,FALSE),0) -> 0 | G5: =IFERROR(VLOOKUP(A5,[1]Monitoramento_Base_somente_Said!$A:$J,10,FALSE),0) -> 0 | H5: =IFERROR(VLOOKUP(A5,[2]Sheet1!$A:$I,4,FALSE),0) -> 0 | I5: =IFERROR(VLOOKUP(A5,[2]Sheet1!$A:$I,5,FALSE),0) -> 0 | J5: =IFERROR(VLOOKUP(A5,[2]Sheet1!$A:$I,6,FALSE),0) -> 0 | K5: =IFERROR(VLOOKUP(A5,[2]Sheet1!$A:$I,7,FALSE),0) -> 0 | L5: =IFERROR(VLOOKUP(A5,[2]Sheet1!$A:$I,8,FALSE),0) -> 0 | M5: =IFERROR(VLOOKUP(A5,[2]Sheet1!$A:$I,9,FALSE),0) -> 0 | N5: =IFERROR(VLOOKUP(A5,[3]Sheet1!$A:$G,2,FALSE),0) -> 0 | O5: =IFERROR(VLOOKUP(A5,[3]Sheet1!$A:$G,3,FALSE),0) -> 0 | P5: =IFERROR(VLOOKUP(A5,[3]Sheet1!$A:$G,4,FALSE),0) -> 0 | Q5: =IFERROR(VLOOKUP(A5,[3]Sheet1!$A:$G,5,FALSE),0) -> 0 | R5: =IFERROR(VLOOKUP(A5,[3]Sheet1!$A:$H,6,FALSE),0) -> 0 | S5: =IFERROR(VLOOKUP(A5,[3]Sheet1!$A:$I,7,FALSE),0) -> 0 | T5: =IF(B5+H5+N5>0,"Sim","Não") -> Não | U5: =IF(C5+I5+O5>0,"Sim","Não") -> Sim | V5: =IF(D5+J5+P5>0,"Sim","Não") -> Não | W5: =IF(E5+K5+Q5>0,"Sim","Não") -> Sim | X5: =IF(F5+L5+R5>0,"Sim","Não") -> Não | Y5: =IF(G5+M5+S5>0,"Sim","Não") -> Não
A6: 120005 | B6: =IFERROR(VLOOKUP(A6,[1]Monitoramento_Base_somente_Said!$A:$J,5,FALSE),0) -> 28090 | C6: =IFERROR(VLOOKUP(A6,[1]Monitoramento_Base_somente_Said!$A:$J,6,FALSE),0) -> 16955565 | D6: =IFERROR(VLOOKUP(A6,[1]Monitoramento_Base_somente_Said!$A:$J,7,FALSE),0) -> 2005 | E6: =IFERROR(VLOOKUP(A6,[1]Monitoramento_Base_somente_Said!$A:$J,8,FALSE),0) -> 16740398 | F6: =IFERROR(VLOOKUP(A6,[1]Monitoramento_Base_somente_Said!$A:$J,9,FALSE),0) -> 0 | G6: =IFERROR(VLOOKUP(A6,[1]Monitoramento_Base_somente_Said!$A:$J,10,FALSE),0) -> 0 | H6: =IFERROR(VLOOKUP(A6,[2]Sheet1!$A:$I,4,FALSE),0) -> 0 | I6: =IFERROR(VLOOKUP(A6,[2]Sheet1!$A:$I,5,FALSE),0) -> 0 | J6: =IFERROR(VLOOKUP(A6,[2]Sheet1!$A:$I,6,FALSE),0) -> 0 | K6: =IFERROR(VLOOKUP(A6,[2]Sheet1!$A:$I,7,FALSE),0) -> 0 | L6: =IFERROR(VLOOKUP(A6,[2]Sheet1!$A:$I,8,FALSE),0) -> 0 | M6: =IFERROR(VLOOKUP(A6,[2]Sheet1!$A:$I,9,FALSE),0) -> 0 | N6: =IFERROR(VLOOKUP(A6,[3]Sheet1!$A:$G,2,FALSE),0) -> 0 | O6: =IFERROR(VLOOKUP(A6,[3]Sheet1!$A:$G,3,FALSE),0) -> 0 | P6: =IFERROR(VLOOKUP(A6,[3]Sheet1!$A:$G,4,FALSE),0) -> 0 | Q6: =IFERROR(VLOOKUP(A6,[3]Sheet1!$A:$G,5,FALSE),0) -> 0 | R6: =IFERROR(VLOOKUP(A6,[3]Sheet1!$A:$H,6,FALSE),0) -> 0 | S6: =IFERROR(VLOOKUP(A6,[3]Sheet1!$A:$I,7,FALSE),0) -> 0 | T6: =IF(B6+H6+N6>0,"Sim","Não") -> Sim | U6: =IF(C6+I6+O6>0,"Sim","Não") -> Sim | V6: =IF(D6+J6+P6>0,"Sim","Não") -> Sim | W6: =IF(E6+K6+Q6>0,"Sim","Não") -> Sim | X6: =IF(F6+L6+R6>0,"Sim","Não") -> Não | Y6: =IF(G6+M6+S6>0,"Sim","Não") -> Não
A7: 120010 | B7: =IFERROR(VLOOKUP(A7,[1]Monitoramento_Base_somente_Said!$A:$J,5,FALSE),0) -> 49696 | C7: =IFERROR(VLOOKUP(A7,[1]Monitoramento_Base_somente_Said!$A:$J,6,FALSE),0) -> 50945400 | D7: =IFERROR(VLOOKUP(A7,[1]Monitoramento_Base_somente_Said!$A:$J,7,FALSE),0) -> 58975 | E7: =IFERROR(VLOOKUP(A7,[1]Monitoramento_Base_somente_Said!$A:$J,8,FALSE),0) -> 53877425 | F7: =IFERROR(VLOOKUP(A7,[1]Monitoramento_Base_somente_Said!$A:$J,9,FALSE),0) -> 0 | G7: =IFERROR(VLOOKUP(A7,[1]Monitoramento_Base_somente_Said!$A:$J,10,FALSE),0) -> 0 | H7: =IFERROR(VLOOKUP(A7,[2]Sheet1!$A:$I,4,FALSE),0) -> 0 | I7: =IFERROR(VLOOKUP(A7,[2]Sheet1!$A:$I,5,FALSE),0) -> 0 | J7: =IFERROR(VLOOKUP(A7,[2]Sheet1!$A:$I,6,FALSE),0) -> 0 | K7: =IFERROR(VLOOKUP(A7,[2]Sheet1!$A:$I,7,FALSE),0) -> 0 | L7: =IFERROR(VLOOKUP(A7,[2]Sheet1!$A:$I,8,FALSE),0) -> 0 | M7: =IFERROR(VLOOKUP(A7,[2]Sheet1!$A:$I,9,FALSE),0) -> 0 | N7: =IFERROR(VLOOKUP(A7,[3]Sheet1!$A:$G,2,FALSE),0) -> 0 | O7: =IFERROR(VLOOKUP(A7,[3]Sheet1!$A:$G,3,FALSE),0) -> 0 | P7: =IFERROR(VLOOKUP(A7,[3]Sheet1!$A:$G,4,FALSE),0) -> 0 | Q7: =IFERROR(VLOOKUP(A7,[3]Sheet1!$A:$G,5,FALSE),0) -> 0 | R7: =IFERROR(VLOOKUP(A7,[3]Sheet1!$A:$H,6,FALSE),0) -> 0 | S7: =IFERROR(VLOOKUP(A7,[3]Sheet1!$A:$I,7,FALSE),0) -> 0 | T7: =IF(B7+H7+N7>0,"Sim","Não") -> Sim | U7: =IF(C7+I7+O7>0,"Sim","Não") -> Sim | V7: =IF(D7+J7+P7>0,"Sim","Não") -> Sim | W7: =IF(E7+K7+Q7>0,"Sim","Não") -> Sim | X7: =IF(F7+L7+R7>0,"Sim","Não") -> Não | Y7: =IF(G7+M7+S7>0,"Sim","Não") -> Não
A8: 120013 | B8: =IFERROR(VLOOKUP(A8,[1]Monitoramento_Base_somente_Said!$A:$J,5,FALSE),0) -> 105145 | C8: =IFERROR(VLOOKUP(A8,[1]Monitoramento_Base_somente_Said!$A:$J,6,FALSE),0) -> 35550204 | D8: =IFERROR(VLOOKUP(A8,[1]Monitoramento_Base_somente_Said!$A:$J,7,FALSE),0) -> 62227 | E8: =IFERROR(VLOOKUP(A8,[1]Monitoramento_Base_somente_Said!$A:$J,8,FALSE),0) -> 31607469 | F8: =IFERROR(VLOOKUP(A8,[1]Monitoramento_Base_somente_Said!$A:$J,9,FALSE),0) -> 0 | G8: =IFERROR(VLOOKUP(A8,[1]Monitoramento_Base_somente_Said!$A:$J,10,FALSE),0) -> 0 | H8: =IFERROR(VLOOKUP(A8,[2]Sheet1!$A:$I,4,FALSE),0) -> 0 | I8: =IFERROR(VLOOKUP(A8,[2]Sheet1!$A:$I,5,FALSE),0) -> 0 | J8: =IFERROR(VLOOKUP(A8,[2]Sheet1!$A:$I,6,FALSE),0) -> 0 | K8: =IFERROR(VLOOKUP(A8,[2]Sheet1!$A:$I,7,FALSE),0) -> 0 | L8: =IFERROR(VLOOKUP(A8,[2]Sheet1!$A:$I,8,FALSE),0) -> 0 | M8: =IFERROR(VLOOKUP(A8,[2]Sheet1!$A:$I,9,FALSE),0) -> 0 | N8: =IFERROR(VLOOKUP(A8,[3]Sheet1!$A:$G,2,FALSE),0) -> 0 | O8: =IFERROR(VLOOKUP(A8,[3]Sheet1!$A:$G,3,FALSE),0) -> 0 | P8: =IFERROR(VLOOKUP(A8,[3]Sheet1!$A:$G,4,FALSE),0) -> 0 | Q8: =IFERROR(VLOOKUP(A8,[3]Sheet1!$A:$G,5,FALSE),0) -> 0 | R8: =IFERROR(VLOOKUP(A8,[3]Sheet1!$A:$H,6,FALSE),0) -> 0 | S8: =IFERROR(VLOOKUP(A8,[3]Sheet1!$A:$I,7,FALSE),0) -> 0 | T8: =IF(B8+H8+N8>0,"Sim","Não") -> Sim | U8: =IF(C8+I8+O8>0,"Sim","Não") -> Sim | V8: =IF(D8+J8+P8>0,"Sim","Não") -> Sim | W8: =IF(E8+K8+Q8>0,"Sim","Não") -> Sim | X8: =IF(F8+L8+R8>0,"Sim","Não") -> Não | Y8: =IF(G8+M8+S8>0,"Sim","Não") -> Não
A9: 120017 | B9: =IFERROR(VLOOKUP(A9,[1]Monitoramento_Base_somente_Said!$A:$J,5,FALSE),0) -> 0 | C9: =IFERROR(VLOOKUP(A9,[1]Monitoramento_Base_somente_Said!$A:$J,6,FALSE),0) -> 10050 | D9: =IFERROR(VLOOKUP(A9,[1]Monitoramento_Base_somente_Said!$A:$J,7,FALSE),0) -> 0 | E9: =IFERROR(VLOOKUP(A9,[1]Monitoramento_Base_somente_Said!$A:$J,8,FALSE),0) -> 9715 | F9: =IFERROR(VLOOKUP(A9,[1]Monitoramento_Base_somente_Said!$A:$J,9,FALSE),0) -> 0 | G9: =IFERROR(VLOOKUP(A9,[1]Monitoramento_Base_somente_Said!$A:$J,10,FALSE),0) -> 0 | H9: =IFERROR(VLOOKUP(A9,[2]Sheet1!$A:$I,4,FALSE),0) -> 0 | I9: =IFERROR(VLOOKUP(A9,[2]Sheet1!$A:$I,5,FALSE),0) -> 0 | J9: =IFERROR(VLOOKUP(A9,[2]Sheet1!$A:$I,6,FALSE),0) -> 0 | K9: =IFERROR(VLOOKUP(A9,[2]Sheet1!$A:$I,7,FALSE),0) -> 0 | L9: =IFERROR(VLOOKUP(A9,[2]Sheet1!$A:$I,8,FALSE),0) -> 0 | M9: =IFERROR(VLOOKUP(A9,[2]Sheet1!$A:$I,9,FALSE),0) -> 0 | N9: =IFERROR(VLOOKUP(A9,[3]Sheet1!$A:$G,2,FALSE),0) -> 0 | O9: =IFERROR(VLOOKUP(A9,[3]Sheet1!$A:$G,3,FALSE),0) -> 0 | P9: =IFERROR(VLOOKUP(A9,[3]Sheet1!$A:$G,4,FALSE),0) -> 0 | Q9: =IFERROR(VLOOKUP(A9,[3]Sheet1!$A:$G,5,FALSE),0) -> 0 | R9: =IFERROR(VLOOKUP(A9,[3]Sheet1!$A:$H,6,FALSE),0) -> 0 | S9: =IFERROR(VLOOKUP(A9,[3]Sheet1!$A:$I,7,FALSE),0) -> 0 | T9: =IF(B9+H9+N9>0,"Sim","Não") -> Não | U9: =IF(C9+I9+O9>0,"Sim","Não") -> Sim | V9: =IF(D9+J9+P9>0,"Sim","Não") -> Não | W9: =IF(E9+K9+Q9>0,"Sim","Não") -> Sim | X9: =IF(F9+L9+R9>0,"Sim","Não") -> Não | Y9: =IF(G9+M9+S9>0,"Sim","Não") -> Não
A10: 120025 | B10: =IFERROR(VLOOKUP(A10,[1]Monitoramento_Base_somente_Said!$A:$J,5,FALSE),0) -> 93807 | C10: =IFERROR(VLOOKUP(A10,[1]Monitoramento_Base_somente_Said!$A:$J,6,FALSE),0) -> 42309027 | D10: =IFERROR(VLOOKUP(A10,[1]Monitoramento_Base_somente_Said!$A:$J,7,FALSE),0) -> 21674 | E10: =IFERROR(VLOOKUP(A10,[1]Monitoramento_Base_somente_Said!$A:$J,8,FALSE),0) -> 38109410 | F10: =IFERROR(VLOOKUP(A10,[1]Monitoramento_Base_somente_Said!$A:$J,9,FALSE),0) -> 0 | G10: =IFERROR(VLOOKUP(A10,[1]Monitoramento_Base_somente_Said!$A:$J,10,FALSE),0) -> 0 | H10: =IFERROR(VLOOKUP(A10,[2]Sheet1!$A:$I,4,FALSE),0) -> 0 | I10: =IFERROR(VLOOKUP(A10,[2]Sheet1!$A:$I,5,FALSE),0) -> 0 | J10: =IFERROR(VLOOKUP(A10,[2]Sheet1!$A:$I,6,FALSE),0) -> 0 | K10: =IFERROR(VLOOKUP(A10,[2]Sheet1!$A:$I,7,FALSE),0) -> 0 | L10: =IFERROR(VLOOKUP(A10,[2]Sheet1!$A:$I,8,FALSE),0) -> 0 | M10: =IFERROR(VLOOKUP(A10,[2]Sheet1!$A:$I,9,FALSE),0) -> 0 | N10: =IFERROR(VLOOKUP(A10,[3]Sheet1!$A:$G,2,FALSE),0) -> 0 | O10: =IFERROR(VLOOKUP(A10,[3]Sheet1!$A:$G,3,FALSE),0) -> 0 | P10: =IFERROR(VLOOKUP(A10,[3]Sheet1!$A:$G,4,FALSE),0) -> 0 | Q10: =IFERROR(VLOOKUP(A10,[3]Sheet1!$A:$G,5,FALSE),0) -> 0 | R10: =IFERROR(VLOOKUP(A10,[3]Sheet1!$A:$H,6,FALSE),0) -> 0 | S10: =IFERROR(VLOOKUP(A10,[3]Sheet1!$A:$I,7,FALSE),0) -> 0 | T10: =IF(B10+H10+N10>0,"Sim","Não") -> Sim | U10: =IF(C10+I10+O10>0,"Sim","Não") -> Sim | V10: =IF(D10+J10+P10>0,"Sim","Não") -> Sim | W10: =IF(E10+K10+Q10>0,"Sim","Não") -> Sim | X10: =IF(F10+L10+R10>0,"Sim","Não") -> Não | Y10: =IF(G10+M10+S10>0,"Sim","Não") -> Não
A11: 120030 | B11: =IFERROR(VLOOKUP(A11,[1]Monitoramento_Base_somente_Said!$A:$J,5,FALSE),0) -> 0 | C11: =IFERROR(VLOOKUP(A11,[1]Monitoramento_Base_somente_Said!$A:$J,6,FALSE),0) -> 0 | D11: =IFERROR(VLOOKUP(A11,[1]Monitoramento_Base_somente_Said!$A:$J,7,FALSE),0) -> 0 | E11: =IFERROR(VLOOKUP(A11,[1]Monitoramento_Base_somente_Said!$A:$J,8,FALSE),0) -> 0 | F11: =IFERROR(VLOOKUP(A11,[1]Monitoramento_Base_somente_Said!$A:$J,9,FALSE),0) -> 0 | G11: =IFERROR(VLOOKUP(A11,[1]Monitoramento_Base_somente_Said!$A:$J,10,FALSE),0) -> 0 | H11: =IFERROR(VLOOKUP(A11,[2]Sheet1!$A:$I,4,FALSE),0) -> 0 | I11: =IFERROR(VLOOKUP(A11,[2]Sheet1!$A:$I,5,FALSE),0) -> 0 | J11: =IFERROR(VLOOKUP(A11,[2]Sheet1!$A:$I,6,FALSE),0) -> 0 | K11: =IFERROR(VLOOKUP(A11,[2]Sheet1!$A:$I,7,FALSE),0) -> 0 | L11: =IFERROR(VLOOKUP(A11,[2]Sheet1!$A:$I,8,FALSE),0) -> 0 | M11: =IFERROR(VLOOKUP(A11,[2]Sheet1!$A:$I,9,FALSE),0) -> 0 | N11: =IFERROR(VLOOKUP(A11,[3]Sheet1!$A:$G,2,FALSE),0) -> 0 | O11: =IFERROR(VLOOKUP(A11,[3]Sheet1!$A:$G,3,FALSE),0) -> 0 | P11: =IFERROR(VLOOKUP(A11,[3]Sheet1!$A:$G,4,FALSE),0) -> 0 | Q11: =IFERROR(VLOOKUP(A11,[3]Sheet1!$A:$G,5,FALSE),0) -> 0 | R11: =IFERROR(VLOOKUP(A11,[3]Sheet1!$A:$H,6,FALSE),0) -> 0 | S11: =IFERROR(VLOOKUP(A11,[3]Sheet1!$A:$I,7,FALSE),0) -> 0 | T11: =IF(B11+H11+N11>0,"Sim","Não") -> Não | U11: =IF(C11+I11+O11>0,"Sim","Não") -> Não | V11: =IF(D11+J11+P11>0,"Sim","Não") -> Não | W11: =IF(E11+K11+Q11>0,"Sim","Não") -> Não | X11: =IF(F11+L11+R11>0,"Sim","Não") -> Não | Y11: =IF(G11+M11+S11>0,"Sim","Não") -> Não
A12: 120032 | B12: =IFERROR(VLOOKUP(A12,[1]Monitoramento_Base_somente_Said!$A:$J,5,FALSE),0) -> 0 | C12: =IFERROR(VLOOKUP(A12,[1]Monitoramento_Base_somente_Said!$A:$J,6,FALSE),0) -> 0 | D12: =IFERROR(VLOOKUP(A12,[1]Monitoramento_Base_somente_Said!$A:$J,7,FALSE),0) -> 0 | E12: =IFERROR(VLOOKUP(A12,[1]Monitoramento_Base_somente_Said!$A:$J,8,FALSE),0) -> 0 | F12: =IFERROR(VLOOKUP(A12,[1]Monitoramento_Base_somente_Said!$A:$J,9,FALSE),0) -> 0 | G12: =IFERROR(VLOOKUP(A12,[1]Monitoramento_Base_somente_Said!$A:$J,10,FALSE),0) -> 0 | H12: =IFERROR(VLOOKUP(A12,[2]Sheet1!$A:$I,4,FALSE),0) -> 0 | I12: =IFERROR(VLOOKUP(A12,[2]Sheet1!$A:$I,5,FALSE),0) -> 0 | J12: =IFERROR(VLOOKUP(A12,[2]Sheet1!$A:$I,6,FALSE),0) -> 0 | K12: =IFERROR(VLOOKUP(A12,[2]Sheet1!$A:$I,7,FALSE),0) -> 0 | L12: =IFERROR(VLOOKUP(A12,[2]Sheet1!$A:$I,8,FALSE),0) -> 0 | M12: =IFERROR(VLOOKUP(A12,[2]Sheet1!$A:$I,9,FALSE),0) -> 0 | N12: =IFERROR(VLOOKUP(A12,[3]Sheet1!$A:$G,2,FALSE),0) -> 0 | O12: =IFERROR(VLOOKUP(A12,[3]Sheet1!$A:$G,3,FALSE),0) -> 0 | P12: =IFERROR(VLOOKUP(A12,[3]Sheet1!$A:$G,4,FALSE),0) -> 0 | Q12: =IFERROR(VLOOKUP(A12,[3]Sheet1!$A:$G,5,FALSE),0) -> 0 | R12: =IFERROR(VLOOKUP(A12,[3]Sheet1!$A:$H,6,FALSE),0) -> 0 | S12: =IFERROR(VLOOKUP(A12,[3]Sheet1!$A:$I,7,FALSE),0) -> 0 | T12: =IF(B12+H12+N12>0,"Sim","Não") -> Não | U12: =IF(C12+I12+O12>0,"Sim","Não") -> Não | V12: =IF(D12+J12+P12>0,"Sim","Não") -> Não | W12: =IF(E12+K12+Q12>0,"Sim","Não") -> Não | X12: =IF(F12+L12+R12>0,"Sim","Não") -> Não | Y12: =IF(G12+M12+S12>0,"Sim","Não") -> Não
A13: 120033 | B13: =IFERROR(VLOOKUP(A13,[1]Monitoramento_Base_somente_Said!$A:$J,5,FALSE),0) -> 9724 | C13: =IFERROR(VLOOKUP(A13,[1]Monitoramento_Base_somente_Said!$A:$J,6,FALSE),0) -> 66752807 | D13: =IFERROR(VLOOKUP(A13,[1]Monitoramento_Base_somente_Said!$A:$J,7,FALSE),0) -> 174946 | E13: =IFERROR(VLOOKUP(A13,[1]Monitoramento_Base_somente_Said!$A:$J,8,FALSE),0) -> 67277077 | F13: =IFERROR(VLOOKUP(A13,[1]Monitoramento_Base_somente_Said!$A:$J,9,FALSE),0) -> 0 | G13: =IFERROR(VLOOKUP(A13,[1]Monitoramento_Base_somente_Said!$A:$J,10,FALSE),0) -> 0 | H13: =IFERROR(VLOOKUP(A13,[2]Sheet1!$A:$I,4,FALSE),0) -> 0 | I13: =IFERROR(VLOOKUP(A13,[2]Sheet1!$A:$I,5,FALSE),0) -> 0 | J13: =IFERROR(VLOOKUP(A13,[2]Sheet1!$A:$I,6,FALSE),0) -> 0 | K13: =IFERROR(VLOOKUP(A13,[2]Sheet1!$A:$I,7,FALSE),0) -> 0 | L13: =IFERROR(VLOOKUP(A13,[2]Sheet1!$A:$I,8,FALSE),0) -> 0 | M13: =IFERROR(VLOOKUP(A13,[2]Sheet1!$A:$I,9,FALSE),0) -> 0 | N13: =IFERROR(VLOOKUP(A13,[3]Sheet1!$A:$G,2,FALSE),0) -> 0 | O13: =IFERROR(VLOOKUP(A13,[3]Sheet1!$A:$G,3,FALSE),0) -> 0 | P13: =IFERROR(VLOOKUP(A13,[3]Sheet1!$A:$G,4,FALSE),0) -> 0 | Q13: =IFERROR(VLOOKUP(A13,[3]Sheet1!$A:$G,5,FALSE),0) -> 0 | R13: =IFERROR(VLOOKUP(A13,[3]Sheet1!$A:$H,6,FALSE),0) -> 0 | S13: =IFERROR(VLOOKUP(A13,[3]Sheet1!$A:$I,7,FALSE),0) -> 0 | T13: =IF(B13+H13+N13>0,"Sim","Não") -> Sim | U13: =IF(C13+I13+O13>0,"Sim","Não") -> Sim | V13: =IF(D13+J13+P13>0,"Sim","Não") -> Sim | W13: =IF(E13+K13+Q13>0,"Sim","Não") -> Sim | X13: =IF(F13+L13+R13>0,"Sim","Não") -> Não | Y13: =IF(G13+M13+S13>0,"Sim","Não") -> Não
A14: 120034 | B14: =IFERROR(VLOOKUP(A14,[1]Monitoramento_Base_somente_Said!$A:$J,5,FALSE),0) -> 0 | C14: =IFERROR(VLOOKUP(A14,[1]Monitoramento_Base_somente_Said!$A:$J,6,FALSE),0) -> 164050500 | D14: =IFERROR(VLOOKUP(A14,[1]Monitoramento_Base_somente_Said!$A:$J,7,FALSE),0) -> 0 | E14: =IFERROR(VLOOKUP(A14,[1]Monitoramento_Base_somente_Said!$A:$J,8,FALSE),0) -> 158582150 | F14: =IFERROR(VLOOKUP(A14,[1]Monitoramento_Base_somente_Said!$A:$J,9,FALSE),0) -> 0 | G14: =IFERROR(VLOOKUP(A14,[1]Monitoramento_Base_somente_Said!$A:$J,10,FALSE),0) -> 0 | H14: =IFERROR(VLOOKUP(A14,[2]Sheet1!$A:$I,4,FALSE),0) -> 0 | I14: =IFERROR(VLOOKUP(A14,[2]Sheet1!$A:$I,5,FALSE),0) -> 0 | J14: =IFERROR(VLOOKUP(A14,[2]Sheet1!$A:$I,6,FALSE),0) -> 0 | K14: =IFERROR(VLOOKUP(A14,[2]Sheet1!$A:$I,7,FALSE),0) -> 0 | L14: =IFERROR(VLOOKUP(A14,[2]Sheet1!$A:$I,8,FALSE),0) -> 0 | M14: =IFERROR(VLOOKUP(A14,[2]Sheet1!$A:$I,9,FALSE),0) -> 0 | N14: =IFERROR(VLOOKUP(A14,[3]Sheet1!$A:$G,2,FALSE),0) -> 0 | O14: =IFERROR(VLOOKUP(A14,[3]Sheet1!$A:$G,3,FALSE),0) -> 0 | P14: =IFERROR(VLOOKUP(A14,[3]Sheet1!$A:$G,4,FALSE),0) -> 0 | Q14: =IFERROR(VLOOKUP(A14,[3]Sheet1!$A:$G,5,FALSE),0) -> 0 | R14: =IFERROR(VLOOKUP(A14,[3]Sheet1!$A:$H,6,FALSE),0) -> 0 | S14: =IFERROR(VLOOKUP(A14,[3]Sheet1!$A:$I,7,FALSE),0) -> 0 | T14: =IF(B14+H14+N14>0,"Sim","Não") -> Não | U14: =IF(C14+I14+O14>0,"Sim","Não") -> Sim | V14: =IF(D14+J14+P14>0,"Sim","Não") -> Não | W14: =IF(E14+K14+Q14>0,"Sim","Não") -> Sim | X14: =IF(F14+L14+R14>0,"Sim","Não") -> Não | Y14: =IF(G14+M14+S14>0,"Sim","Não") -> Não
A15: 120035 | B15: =IFERROR(VLOOKUP(A15,[1]Monitoramento_Base_somente_Said!$A:$J,5,FALSE),0) -> 79873 | C15: =IFERROR(VLOOKUP(A15,[1]Monitoramento_Base_somente_Said!$A:$J,6,FALSE),0) -> 39030724 | D15: =IFERROR(VLOOKUP(A15,[1]Monitoramento_Base_somente_Said!$A:$J,7,FALSE),0) -> 178463 | E15: =IFERROR(VLOOKUP(A15,[1]Monitoramento_Base_somente_Said!$A:$J,8,FALSE),0) -> 40024775 | F15: =IFERROR(VLOOKUP(A15,[1]Monitoramento_Base_somente_Said!$A:$J,9,FALSE),0) -> 0 | G15: =IFERROR(VLOOKUP(A15,[1]Monitoramento_Base_somente_Said!$A:$J,10,FALSE),0) -> 0 | H15: =IFERROR(VLOOKUP(A15,[2]Sheet1!$A:$I,4,FALSE),0) -> 0 | I15: =IFERROR(VLOOKUP(A15,[2]Sheet1!$A:$I,5,FALSE),0) -> 0 | J15: =IFERROR(VLOOKUP(A15,[2]Sheet1!$A:$I,6,FALSE),0) -> 0 | K15: =IFERROR(VLOOKUP(A15,[2]Sheet1!$A:$I,7,FALSE),0) -> 0 | L15: =IFERROR(VLOOKUP(A15,[2]Sheet1!$A:$I,8,FALSE),0) -> 0 | M15: =IFERROR(VLOOKUP(A15,[2]Sheet1!$A:$I,9,FALSE),0) -> 0 | N15: =IFERROR(VLOOKUP(A15,[3]Sheet1!$A:$G,2,FALSE),0) -> 0 | O15: =IFERROR(VLOOKUP(A15,[3]Sheet1!$A:$G,3,FALSE),0) -> 0 | P15: =IFERROR(VLOOKUP(A15,[3]Sheet1!$A:$G,4,FALSE),0) -> 0 | Q15: =IFERROR(VLOOKUP(A15,[3]Sheet1!$A:$G,5,FALSE),0) -> 0 | R15: =IFERROR(VLOOKUP(A15,[3]Sheet1!$A:$H,6,FALSE),0) -> 0 | S15: =IFERROR(VLOOKUP(A15,[3]Sheet1!$A:$I,7,FALSE),0) -> 0 | T15: =IF(B15+H15+N15>0,"Sim","Não") -> Sim | U15: =IF(C15+I15+O15>0,"Sim","Não") -> Sim | V15: =IF(D15+J15+P15>0,"Sim","Não") -> Sim | W15: =IF(E15+K15+Q15>0,"Sim","Não") -> Sim | X15: =IF(F15+L15+R15>0,"Sim","Não") -> Não | Y15: =IF(G15+M15+S15>0,"Sim","Não") -> Não
A16: 120080 | B16: =IFERROR(VLOOKUP(A16,[1]Monitoramento_Base_somente_Said!$A:$J,5,FALSE),0) -> 11236 | C16: =IFERROR(VLOOKUP(A16,[1]Monitoramento_Base_somente_Said!$A:$J,6,FALSE),0) -> 47500364 | D16: =IFERROR(VLOOKUP(A16,[1]Monitoramento_Base_somente_Said!$A:$J,7,FALSE),0) -> 176233 | E16: =IFERROR(VLOOKUP(A16,[1]Monitoramento_Base_somente_Said!$A:$J,8,FALSE),0) -> 41876606 | F16: =IFERROR(VLOOKUP(A16,[1]Monitoramento_Base_somente_Said!$A:$J,9,FALSE),0) -> 0 | G16: =IFERROR(VLOOKUP(A16,[1]Monitoramento_Base_somente_Said!$A:$J,10,FALSE),0) -> 0 | H16: =IFERROR(VLOOKUP(A16,[2]Sheet1!$A:$I,4,FALSE),0) -> 0 | I16: =IFERROR(VLOOKUP(A16,[2]Sheet1!$A:$I,5,FALSE),0) -> 0 | J16: =IFERROR(VLOOKUP(A16,[2]Sheet1!$A:$I,6,FALSE),0) -> 0 | K16: =IFERROR(VLOOKUP(A16,[2]Sheet1!$A:$I,7,FALSE),0) -> 0 | L16: =IFERROR(VLOOKUP(A16,[2]Sheet1!$A:$I,8,FALSE),0) -> 0 | M16: =IFERROR(VLOOKUP(A16,[2]Sheet1!$A:$I,9,FALSE),0) -> 0 | N16: =IFERROR(VLOOKUP(A16,[3]Sheet1!$A:$G,2,FALSE),0) -> 0 | O16: =IFERROR(VLOOKUP(A16,[3]Sheet1!$A:$G,3,FALSE),0) -> 0 | P16: =IFERROR(VLOOKUP(A16,[3]Sheet1!$A:$G,4,FALSE),0) -> 0 | Q16: =IFERROR(VLOOKUP(A16,[3]Sheet1!$A:$G,5,FALSE),0) -> 0 | R16: =IFERROR(VLOOKUP(A16,[3]Sheet1!$A:$H,6,FALSE),0) -> 0 | S16: =IFERROR(VLOOKUP(A16,[3]Sheet1!$A:$I,7,FALSE),0) -> 0 | T16: =IF(B16+H16+N16>0,"Sim","Não") -> Sim | U16: =IF(C16+I16+O16>0,"Sim","Não") -> Sim | V16: =IF(D16+J16+P16>0,"Sim","Não") -> Sim | W16: =IF(E16+K16+Q16>0,"Sim","Não") -> Sim | X16: =IF(F16+L16+R16>0,"Sim","Não") -> Não | Y16: =IF(G16+M16+S16>0,"Sim","Não") -> Não
... A2477: 260950 | B2477: =IFERROR(VLOOKUP(A2477,[1]Monitoramento_Base_somente_Said!$A:$J,5,FALSE),0) -> 401 | C2477: =IFERROR(VLOOKUP(A2477,[1]Monitoramento_Base_somente_Said!$A:$J,6,FALSE),0) -> 41333752 | D2477: =IFERROR(VLOOKUP(A2477,[1]Monitoramento_Base_somente_Said!$A:$J,7,FALSE),0) -> 23153 | E2477: =IFERROR(VLOOKUP(A2477,[1]Monitoramento_Base_somente_Said!$A:$J,8,FALSE),0) -> 38993042 | F2477: =IFERROR(VLOOKUP(A2477,[1]Monitoramento_Base_somente_Said!$A:$J,9,FALSE),0) -> 0 | G2477: =IFERROR(VLOOKUP(A2477,[1]Monitoramento_Base_somente_Said!$A:$J,10,FALSE),0) -> 0 | H2477: =IFERROR(VLOOKUP(A2477,[2]Sheet1!$A:$I,4,FALSE),0) -> 0 | I2477: =IFERROR(VLOOKUP(A2477,[2]Sheet1!$A:$I,5,FALSE),0) -> 0 | J2477: =IFERROR(VLOOKUP(A2477,[2]Sheet1!$A:$I,6,FALSE),0) -> 0 | K2477: =IFERROR(VLOOKUP(A2477,[2]Sheet1!$A:$I,7,FALSE),0) -> 0 | L2477: =IFERROR(VLOOKUP(A2477,[2]Sheet1!$A:$I,8,FALSE),0) -> 0 | M2477: =IFERROR(VLOOKUP(A2477,[2]Sheet1!$A:$I,9,FALSE),0) -> 0 | N2477: =IFERROR(VLOOKUP(A2477,[3]Sheet1!$A:$G,2,FALSE),0) -> 0 | O2477: =IFERROR(VLOOKUP(A2477,[3]Sheet1!$A:$G,3,FALSE),0) -> 0 | P2477: =IFERROR(VLOOKUP(A2477,[3]Sheet1!$A:$G,4,FALSE),0) -> 0 | Q2477: =IFERROR(VLOOKUP(A2477,[3]Sheet1!$A:$G,5,FALSE),0) -> 0 | R2477: =IFERROR(VLOOKUP(A2477,[3]Sheet1!$A:$H,6,FALSE),0) -> 0 | S2477: =IFERROR(VLOOKUP(A2477,[3]Sheet1!$A:$I,7,FALSE),0) -> 0 | T2477: =IF(B2477+H2477+N2477>0,"Sim","Não") -> Sim | U2477: =IF(C2477+I2477+O2477>0,"Sim","Não") -> Sim | V2477: =IF(D2477+J2477+P2477>0,"Sim","Não") -> Sim | W2477: =IF(E2477+K2477+Q2477>0,"Sim","Não") -> Sim | X2477: =IF(F2477+L2477+R2477>0,"Sim","Não") -> Não | Y2477: =IF(G2477+M2477+S2477>0,"Sim","Não") -> Não
A2478: 260960 | B2478: 3357157 | C2478: 407033082 | D2478: 1772998 | E2478: 278012725 | F2478: =IFERROR(VLOOKUP(A2478,[1]Monitoramento_Base_somente_Said!$A:$J,9,FALSE),0) -> 0 | G2478: =IFERROR(VLOOKUP(A2478,[1]Monitoramento_Base_somente_Said!$A:$J,10,FALSE),0) -> 0 | H2478: =IFERROR(VLOOKUP(A2478,[2]Sheet1!$A:$I,4,FALSE),0) -> 0 | I2478: =IFERROR(VLOOKUP(A2478,[2]Sheet1!$A:$I,5,FALSE),0) -> 0 | J2478: =IFERROR(VLOOKUP(A2478,[2]Sheet1!$A:$I,6,FALSE),0) -> 0 | K2478: =IFERROR(VLOOKUP(A2478,[2]Sheet1!$A:$I,7,FALSE),0) -> 0 | L2478: =IFERROR(VLOOKUP(A2478,[2]Sheet1!$A:$I,8,FALSE),0) -> 0 | M2478: =IFERROR(VLOOKUP(A2478,[2]Sheet1!$A:$I,9,FALSE),0) -> 0 | N2478: =IFERROR(VLOOKUP(A2478,[3]Sheet1!$A:$G,2,FALSE),0) -> 0 | O2478: =IFERROR(VLOOKUP(A2478,[3]Sheet1!$A:$G,3,FALSE),0) -> 0 | P2478: =IFERROR(VLOOKUP(A2478,[3]Sheet1!$A:$G,4,FALSE),0) -> 0 | Q2478: 0 | R2478: =IFERROR(VLOOKUP(A2478,[3]Sheet1!$A:$H,6,FALSE),0) -> 0 | S2478: =IFERROR(VLOOKUP(A2478,[3]Sheet1!$A:$I,7,FALSE),0) -> 0 | T2478: =IF(B2478+H2478+N2478>0,"Sim","Não") -> Sim | U2478: =IF(C2478+I2478+O2478>0,"Sim","Não") -> Sim | V2478: =IF(D2478+J2478+P2478>0,"Sim","Não") -> Sim | W2478: =IF(E2478+K2478+Q2478>0,"Sim","Não") -> Sim | X2478: =IF(F2478+L2478+R2478>0,"Sim","Não") -> Não | Y2478: =IF(G2478+M2478+S2478>0,"Sim","Não") -> Não
A2479: 260970 | B2479: =IFERROR(VLOOKUP(A2479,[1]Monitoramento_Base_somente_Said!$A:$J,5,FALSE),0) -> 114157 | C2479: =IFERROR(VLOOKUP(A2479,[1]Monitoramento_Base_somente_Said!$A:$J,6,FALSE),0) -> 31538338 | D2479: =IFERROR(VLOOKUP(A2479,[1]Monitoramento_Base_somente_Said!$A:$J,7,FALSE),0) -> 276366 | E2479: =IFERROR(VLOOKUP(A2479,[1]Monitoramento_Base_somente_Said!$A:$J,8,FALSE),0) -> 28740299 | F2479: =IFERROR(VLOOKUP(A2479,[1]Monitoramento_Base_somente_Said!$A:$J,9,FALSE),0) -> 0 | G2479: =IFERROR(VLOOKUP(A2479,[1]Monitoramento_Base_somente_Said!$A:$J,10,FALSE),0) -> 0 | H2479: =IFERROR(VLOOKUP(A2479,[2]Sheet1!$A:$I,4,FALSE),0) -> 0 | I2479: =IFERROR(VLOOKUP(A2479,[2]Sheet1!$A:$I,5,FALSE),0) -> 0 | J2479: =IFERROR(VLOOKUP(A2479,[2]Sheet1!$A:$I,6,FALSE),0) -> 0 | K2479: =IFERROR(VLOOKUP(A2479,[2]Sheet1!$A:$I,7,FALSE),0) -> 0 | L2479: =IFERROR(VLOOKUP(A2479,[2]Sheet1!$A:$I,8,FALSE),0) -> 0 | M2479: =IFERROR(VLOOKUP(A2479,[2]Sheet1!$A:$I,9,FALSE),0) -> 0 | N2479: =IFERROR(VLOOKUP(A2479,[3]Sheet1!$A:$G,2,FALSE),0) -> 0 | O2479: =IFERROR(VLOOKUP(A2479,[3]Sheet1!$A:$G,3,FALSE),0) -> 0 | P2479: =IFERROR(VLOOKUP(A2479,[3]Sheet1!$A:$G,4,FALSE),0) -> 0 | Q2479: =IFERROR(VLOOKUP(A2479,[3]Sheet1!$A:$G,5,FALSE),0) -> 0 | R2479: =IFERROR(VLOOKUP(A2479,[3]Sheet1!$A:$H,6,FALSE),0) -> 0 | S2479: =IFERROR(VLOOKUP(A2479,[3]Sheet1!$A:$I,7,FALSE),0) -> 0 | T2479: =IF(B2479+H2479+N2479>0,"Sim","Não") -> Sim | U2479: =IF(C2479+I2479+O2479>0,"Sim","Não") -> Sim | V2479: =IF(D2479+J2479+P2479>0,"Sim","Não") -> Sim | W2479: =IF(E2479+K2479+Q2479>0,"Sim","Não") -> Sim | X2479: =IF(F2479+L2479+R2479>0,"Sim","Não") -> Não | Y2479: =IF(G2479+M2479+S2479>0,"Sim","Não") -> Não
A2480: 260980 | B2480: =IFERROR(VLOOKUP(A2480,[1]Monitoramento_Base_somente_Said!$A:$J,5,FALSE),0) -> 0 | C2480: =IFERROR(VLOOKUP(A2480,[1]Monitoramento_Base_somente_Said!$A:$J,6,FALSE),0) -> 1374480 | D2480: =IFERROR(VLOOKUP(A2480,[1]Monitoramento_Base_somente_Said!$A:$J,7,FALSE),0) -> 0 | E2480: =IFERROR(VLOOKUP(A2480,[1]Monitoramento_Base_somente_Said!$A:$J,8,FALSE),0) -> 1328664 | F2480: =IFERROR(VLOOKUP(A2480,[1]Monitoramento_Base_somente_Said!$A:$J,9,FALSE),0) -> 0 | G2480: =IFERROR(VLOOKUP(A2480,[1]Monitoramento_Base_somente_Said!$A:$J,10,FALSE),0) -> 0 | H2480: =IFERROR(VLOOKUP(A2480,[2]Sheet1!$A:$I,4,FALSE),0) -> 0 | I2480: =IFERROR(VLOOKUP(A2480,[2]Sheet1!$A:$I,5,FALSE),0) -> 0 | J2480: =IFERROR(VLOOKUP(A2480,[2]Sheet1!$A:$I,6,FALSE),0) -> 0 | K2480: =IFERROR(VLOOKUP(A2480,[2]Sheet1!$A:$I,7,FALSE),0) -> 0 | L2480: =IFERROR(VLOOKUP(A2480,[2]Sheet1!$A:$I,8,FALSE),0) -> 0 | M2480: =IFERROR(VLOOKUP(A2480,[2]Sheet1!$A:$I,9,FALSE),0) -> 0 | N2480: =IFERROR(VLOOKUP(A2480,[3]Sheet1!$A:$G,2,FALSE),0) -> 0 | O2480: =IFERROR(VLOOKUP(A2480,[3]Sheet1!$A:$G,3,FALSE),0) -> 0 | P2480: =IFERROR(VLOOKUP(A2480,[3]Sheet1!$A:$G,4,FALSE),0) -> 0 | Q2480: =IFERROR(VLOOKUP(A2480,[3]Sheet1!$A:$G,5,FALSE),0) -> 0 | R2480: =IFERROR(VLOOKUP(A2480,[3]Sheet1!$A:$H,6,FALSE),0) -> 0 | S2480: =IFERROR(VLOOKUP(A2480,[3]Sheet1!$A:$I,7,FALSE),0) -> 0 | T2480: =IF(B2480+H2480+N2480>0,"Sim","Não") -> Não | U2480: =IF(C2480+I2480+O2480>0,"Sim","Não") -> Sim | V2480: =IF(D2480+J2480+P2480>0,"Sim","Não") -> Não | W2480: =IF(E2480+K2480+Q2480>0,"Sim","Não") -> Sim | X2480: =IF(F2480+L2480+R2480>0,"Sim","Não") -> Não | Y2480: =IF(G2480+M2480+S2480>0,"Sim","Não") -> Não
A2481: 260990 | B2481: =IFERROR(VLOOKUP(A2481,[1]Monitoramento_Base_somente_Said!$A:$J,5,FALSE),0) -> 100 | C2481: =IFERROR(VLOOKUP(A2481,[1]Monitoramento_Base_somente_Said!$A:$J,6,FALSE),0) -> 37796939 | D2481: =IFERROR(VLOOKUP(A2481,[1]Monitoramento_Base_somente_Said!$A:$J,7,FALSE),0) -> 2 | E2481: =IFERROR(VLOOKUP(A2481,[1]Monitoramento_Base_somente_Said!$A:$J,8,FALSE),0) -> 37359257 | F2481: =IFERROR(VLOOKUP(A2481,[1]Monitoramento_Base_somente_Said!$A:$J,9,FALSE),0) -> 0 | G2481: =IFERROR(VLOOKUP(A2481,[1]Monitoramento_Base_somente_Said!$A:$J,10,FALSE),0) -> 0 | H2481: =IFERROR(VLOOKUP(A2481,[2]Sheet1!$A:$I,4,FALSE),0) -> 0 | I2481: =IFERROR(VLOOKUP(A2481,[2]Sheet1!$A:$I,5,FALSE),0) -> 0 | J2481: =IFERROR(VLOOKUP(A2481,[2]Sheet1!$A:$I,6,FALSE),0) -> 0 | K2481: =IFERROR(VLOOKUP(A2481,[2]Sheet1!$A:$I,7,FALSE),0) -> 0 | L2481: =IFERROR(VLOOKUP(A2481,[2]Sheet1!$A:$I,8,FALSE),0) -> 0 | M2481: =IFERROR(VLOOKUP(A2481,[2]Sheet1!$A:$I,9,FALSE),0) -> 0 | N2481: =IFERROR(VLOOKUP(A2481,[3]Sheet1!$A:$G,2,FALSE),0) -> 0 | O2481: =IFERROR(VLOOKUP(A2481,[3]Sheet1!$A:$G,3,FALSE),0) -> 0 | P2481: =IFERROR(VLOOKUP(A2481,[3]Sheet1!$A:$G,4,FALSE),0) -> 0 | Q2481: =IFERROR(VLOOKUP(A2481,[3]Sheet1!$A:$G,5,FALSE),0) -> 0 | R2481: =IFERROR(VLOOKUP(A2481,[3]Sheet1!$A:$H,6,FALSE),0) -> 0 | S2481: =IFERROR(VLOOKUP(A2481,[3]Sheet1!$A:$I,7,FALSE),0) -> 0 | T2481: =IF(B2481+H2481+N2481>0,"Sim","Não") -> Sim | U2481: =IF(C2481+I2481+O2481>0,"Sim","Não") -> Sim | V2481: =IF(D2481+J2481+P2481>0,"Sim","Não") -> Sim | W2481: =IF(E2481+K2481+Q2481>0,"Sim","Não") -> Sim | X2481: =IF(F2481+L2481+R2481>0,"Sim","Não") -> Não | Y2481: =IF(G2481+M2481+S2481>0,"Sim","Não") -> Não
A2482: 261000 | B2482: =IFERROR(VLOOKUP(A2482,[1]Monitoramento_Base_somente_Said!$A:$J,5,FALSE),0) -> 10456719 | C2482: =IFERROR(VLOOKUP(A2482,[1]Monitoramento_Base_somente_Said!$A:$J,6,FALSE),0) -> 372527844 | D2482: =IFERROR(VLOOKUP(A2482,[1]Monitoramento_Base_somente_Said!$A:$J,7,FALSE),0) -> 46748 | E2482: =IFERROR(VLOOKUP(A2482,[1]Monitoramento_Base_somente_Said!$A:$J,8,FALSE),0) -> 412498301 | F2482: =IFERROR(VLOOKUP(A2482,[1]Monitoramento_Base_somente_Said!$A:$J,9,FALSE),0) -> 0 | G2482: =IFERROR(VLOOKUP(A2482,[1]Monitoramento_Base_somente_Said!$A:$J,10,FALSE),0) -> 0 | H2482: =IFERROR(VLOOKUP(A2482,[2]Sheet1!$A:$I,4,FALSE),0) -> 0 | I2482: =IFERROR(VLOOKUP(A2482,[2]Sheet1!$A:$I,5,FALSE),0) -> 0 | J2482: =IFERROR(VLOOKUP(A2482,[2]Sheet1!$A:$I,6,FALSE),0) -> 0 | K2482: =IFERROR(VLOOKUP(A2482,[2]Sheet1!$A:$I,7,FALSE),0) -> 0 | L2482: =IFERROR(VLOOKUP(A2482,[2]Sheet1!$A:$I,8,FALSE),0) -> 0 | M2482: =IFERROR(VLOOKUP(A2482,[2]Sheet1!$A:$I,9,FALSE),0) -> 0 | N2482: =IFERROR(VLOOKUP(A2482,[3]Sheet1!$A:$G,2,FALSE),0) -> 0 | O2482: =IFERROR(VLOOKUP(A2482,[3]Sheet1!$A:$G,3,FALSE),0) -> 0 | P2482: =IFERROR(VLOOKUP(A2482,[3]Sheet1!$A:$G,4,FALSE),0) -> 0 | Q2482: =IFERROR(VLOOKUP(A2482,[3]Sheet1!$A:$G,5,FALSE),0) -> 0 | R2482: =IFERROR(VLOOKUP(A2482,[3]Sheet1!$A:$H,6,FALSE),0) -> 0 | S2482: =IFERROR(VLOOKUP(A2482,[3]Sheet1!$A:$I,7,FALSE),0) -> 0 | T2482: =IF(B2482+H2482+N2482>0,"Sim","Não") -> Sim | U2482: =IF(C2482+I2482+O2482>0,"Sim","Não") -> Sim | V2482: =IF(D2482+J2482+P2482>0,"Sim","Não") -> Sim | W2482: =IF(E2482+K2482+Q2482>0,"Sim","Não") -> Sim | X2482: =IF(F2482+L2482+R2482>0,"Sim","Não") -> Não | Y2482: =IF(G2482+M2482+S2482>0,"Sim","Não") -> Não
A2483: 261010 | B2483: =IFERROR(VLOOKUP(A2483,[1]Monitoramento_Base_somente_Said!$A:$J,5,FALSE),0) -> 330 | C2483: =IFERROR(VLOOKUP(A2483,[1]Monitoramento_Base_somente_Said!$A:$J,6,FALSE),0) -> 1674635 | D2483: =IFERROR(VLOOKUP(A2483,[1]Monitoramento_Base_somente_Said!$A:$J,7,FALSE),0) -> 7836 | E2483: =IFERROR(VLOOKUP(A2483,[1]Monitoramento_Base_somente_Said!$A:$J,8,FALSE),0) -> 1522295 | F2483: =IFERROR(VLOOKUP(A2483,[1]Monitoramento_Base_somente_Said!$A:$J,9,FALSE),0) -> 0 | G2483: =IFERROR(VLOOKUP(A2483,[1]Monitoramento_Base_somente_Said!$A:$J,10,FALSE),0) -> 0 | H2483: =IFERROR(VLOOKUP(A2483,[2]Sheet1!$A:$I,4,FALSE),0) -> 0 | I2483: =IFERROR(VLOOKUP(A2483,[2]Sheet1!$A:$I,5,FALSE),0) -> 0 | J2483: =IFERROR(VLOOKUP(A2483,[2]Sheet1!$A:$I,6,FALSE),0) -> 0 | K2483: =IFERROR(VLOOKUP(A2483,[2]Sheet1!$A:$I,7,FALSE),0) -> 0 | L2483: =IFERROR(VLOOKUP(A2483,[2]Sheet1!$A:$I,8,FALSE),0) -> 0 | M2483: =IFERROR(VLOOKUP(A2483,[2]Sheet1!$A:$I,9,FALSE),0) -> 0 | N2483: =IFERROR(VLOOKUP(A2483,[3]Sheet1!$A:$G,2,FALSE),0) -> 0 | O2483: =IFERROR(VLOOKUP(A2483,[3]Sheet1!$A:$G,3,FALSE),0) -> 0 | P2483: =IFERROR(VLOOKUP(A2483,[3]Sheet1!$A:$G,4,FALSE),0) -> 0 | Q2483: =IFERROR(VLOOKUP(A2483,[3]Sheet1!$A:$G,5,FALSE),0) -> 0 | R2483: =IFERROR(VLOOKUP(A2483,[3]Sheet1!$A:$H,6,FALSE),0) -> 0 | S2483: =IFERROR(VLOOKUP(A2483,[3]Sheet1!$A:$I,7,FALSE),0) -> 0 | T2483: =IF(B2483+H2483+N2483>0,"Sim","Não") -> Sim | U2483: =IF(C2483+I2483+O2483>0,"Sim","Não") -> Sim | V2483: =IF(D2483+J2483+P2483>0,"Sim","Não") -> Sim | W2483: =IF(E2483+K2483+Q2483>0,"Sim","Não") -> Sim | X2483: =IF(F2483+L2483+R2483>0,"Sim","Não") -> Não | Y2483: =IF(G2483+M2483+S2483>0,"Sim","Não") -> Não
A2484: 261020 | B2484: =IFERROR(VLOOKUP(A2484,[1]Monitoramento_Base_somente_Said!$A:$J,5,FALSE),0) -> 720383 | C2484: =IFERROR(VLOOKUP(A2484,[1]Monitoramento_Base_somente_Said!$A:$J,6,FALSE),0) -> 35543604 | D2484: =IFERROR(VLOOKUP(A2484,[1]Monitoramento_Base_somente_Said!$A:$J,7,FALSE),0) -> 584277 | E2484: =IFERROR(VLOOKUP(A2484,[1]Monitoramento_Base_somente_Said!$A:$J,8,FALSE),0) -> 26247355 | F2484: =IFERROR(VLOOKUP(A2484,[1]Monitoramento_Base_somente_Said!$A:$J,9,FALSE),0) -> 0 | G2484: =IFERROR(VLOOKUP(A2484,[1]Monitoramento_Base_somente_Said!$A:$J,10,FALSE),0) -> 0 | H2484: =IFERROR(VLOOKUP(A2484,[2]Sheet1!$A:$I,4,FALSE),0) -> 0 | I2484: =IFERROR(VLOOKUP(A2484,[2]Sheet1!$A:$I,5,FALSE),0) -> 0 | J2484: =IFERROR(VLOOKUP(A2484,[2]Sheet1!$A:$I,6,FALSE),0) -> 0 | K2484: =IFERROR(VLOOKUP(A2484,[2]Sheet1!$A:$I,7,FALSE),0) -> 0 | L2484: =IFERROR(VLOOKUP(A2484,[2]Sheet1!$A:$I,8,FALSE),0) -> 0 | M2484: =IFERROR(VLOOKUP(A2484,[2]Sheet1!$A:$I,9,FALSE),0) -> 0 | N2484: =IFERROR(VLOOKUP(A2484,[3]Sheet1!$A:$G,2,FALSE),0) -> 0 | O2484: =IFERROR(VLOOKUP(A2484,[3]Sheet1!$A:$G,3,FALSE),0) -> 0 | P2484: =IFERROR(VLOOKUP(A2484,[3]Sheet1!$A:$G,4,FALSE),0) -> 0 | Q2484: =IFERROR(VLOOKUP(A2484,[3]Sheet1!$A:$G,5,FALSE),0) -> 0 | R2484: =IFERROR(VLOOKUP(A2484,[3]Sheet1!$A:$H,6,FALSE),0) -> 0 | S2484: =IFERROR(VLOOKUP(A2484,[3]Sheet1!$A:$I,7,FALSE),0) -> 0 | T2484: =IF(B2484+H2484+N2484>0,"Sim","Não") -> Sim | U2484: =IF(C2484+I2484+O2484>0,"Sim","Não") -> Sim | V2484: =IF(D2484+J2484+P2484>0,"Sim","Não") -> Sim | W2484: =IF(E2484+K2484+Q2484>0,"Sim","Não") -> Sim | X2484: =IF(F2484+L2484+R2484>0,"Sim","Não") -> Não | Y2484: =IF(G2484+M2484+S2484>0,"Sim","Não") -> Não
A2485: 261030 | B2485: =IFERROR(VLOOKUP(A2485,[1]Monitoramento_Base_somente_Said!$A:$J,5,FALSE),0) -> 0 | C2485: =IFERROR(VLOOKUP(A2485,[1]Monitoramento_Base_somente_Said!$A:$J,6,FALSE),0) -> 4482150 | D2485: =IFERROR(VLOOKUP(A2485,[1]Monitoramento_Base_somente_Said!$A:$J,7,FALSE),0) -> 0 | E2485: =IFERROR(VLOOKUP(A2485,[1]Monitoramento_Base_somente_Said!$A:$J,8,FALSE),0) -> 4332745 | F2485: =IFERROR(VLOOKUP(A2485,[1]Monitoramento_Base_somente_Said!$A:$J,9,FALSE),0) -> 0 | G2485: =IFERROR(VLOOKUP(A2485,[1]Monitoramento_Base_somente_Said!$A:$J,10,FALSE),0) -> 0 | H2485: =IFERROR(VLOOKUP(A2485,[2]Sheet1!$A:$I,4,FALSE),0) -> 0 | I2485: =IFERROR(VLOOKUP(A2485,[2]Sheet1!$A:$I,5,FALSE),0) -> 0 | J2485: =IFERROR(VLOOKUP(A2485,[2]Sheet1!$A:$I,6,FALSE),0) -> 0 | K2485: =IFERROR(VLOOKUP(A2485,[2]Sheet1!$A:$I,7,FALSE),0) -> 0 | L2485: =IFERROR(VLOOKUP(A2485,[2]Sheet1!$A:$I,8,FALSE),0) -> 0 | M2485: =IFERROR(VLOOKUP(A2485,[2]Sheet1!$A:$I,9,FALSE),0) -> 0 | N2485: =IFERROR(VLOOKUP(A2485,[3]Sheet1!$A:$G,2,FALSE),0) -> 0 | O2485: =IFERROR(VLOOKUP(A2485,[3]Sheet1!$A:$G,3,FALSE),0) -> 0 | P2485: =IFERROR(VLOOKUP(A2485,[3]Sheet1!$A:$G,4,FALSE),0) -> 0 | Q2485: =IFERROR(VLOOKUP(A2485,[3]Sheet1!$A:$G,5,FALSE),0) -> 0 | R2485: =IFERROR(VLOOKUP(A2485,[3]Sheet1!$A:$H,6,FALSE),0) -> 0 | S2485: =IFERROR(VLOOKUP(A2485,[3]Sheet1!$A:$I,7,FALSE),0) -> 0 | T2485: =IF(B2485+H2485+N2485>0,"Sim","Não") -> Não | U2485: =IF(C2485+I2485+O2485>0,"Sim","Não") -> Sim | V2485: =IF(D2485+J2485+P2485>0,"Sim","Não") -> Não | W2485: =IF(E2485+K2485+Q2485>0,"Sim","Não") -> Sim | X2485: =IF(F2485+L2485+R2485>0,"Sim","Não") -> Não | Y2485: =IF(G2485+M2485+S2485>0,"Sim","Não") -> Não
A2486: 261040 | B2486: =IFERROR(VLOOKUP(A2486,[1]Monitoramento_Base_somente_Said!$A:$J,5,FALSE),0) -> 2476 | C2486: =IFERROR(VLOOKUP(A2486,[1]Monitoramento_Base_somente_Said!$A:$J,6,FALSE),0) -> 476669 | D2486: =IFERROR(VLOOKUP(A2486,[1]Monitoramento_Base_somente_Said!$A:$J,7,FALSE),0) -> 0 | E2486: =IFERROR(VLOOKUP(A2486,[1]Monitoramento_Base_somente_Said!$A:$J,8,FALSE),0) -> 473719 | F2486: =IFERROR(VLOOKUP(A2486,[1]Monitoramento_Base_somente_Said!$A:$J,9,FALSE),0) -> 0 | G2486: =IFERROR(VLOOKUP(A2486,[1]Monitoramento_Base_somente_Said!$A:$J,10,FALSE),0) -> 0 | H2486: =IFERROR(VLOOKUP(A2486,[2]Sheet1!$A:$I,4,FALSE),0) -> 0 | I2486: =IFERROR(VLOOKUP(A2486,[2]Sheet1!$A:$I,5,FALSE),0) -> 0 | J2486: =IFERROR(VLOOKUP(A2486,[2]Sheet1!$A:$I,6,FALSE),0) -> 0 | K2486: =IFERROR(VLOOKUP(A2486,[2]Sheet1!$A:$I,7,FALSE),0) -> 0 | L2486: =IFERROR(VLOOKUP(A2486,[2]Sheet1!$A:$I,8,FALSE),0) -> 0 | M2486: =IFERROR(VLOOKUP(A2486,[2]Sheet1!$A:$I,9,FALSE),0) -> 0 | N2486: =IFERROR(VLOOKUP(A2486,[3]Sheet1!$A:$G,2,FALSE),0) -> 0 | O2486: =IFERROR(VLOOKUP(A2486,[3]Sheet1!$A:$G,3,FALSE),0) -> 0 | P2486: =IFERROR(VLOOKUP(A2486,[3]Sheet1!$A:$G,4,FALSE),0) -> 0 | Q2486: =IFERROR(VLOOKUP(A2486,[3]Sheet1!$A:$G,5,FALSE),0) -> 0 | R2486: =IFERROR(VLOOKUP(A2486,[3]Sheet1!$A:$H,6,FALSE),0) -> 0 | S2486: =IFERROR(VLOOKUP(A2486,[3]Sheet1!$A:$I,7,FALSE),0) -> 0 | T2486: =IF(B2486+H2486+N2486>0,"Sim","Não") -> Sim | U2486: =IF(C2486+I2486+O2486>0,"Sim","Não") -> Sim | V2486: =IF(D2486+J2486+P2486>0,"Sim","Não") -> Não | W2486: =IF(E2486+K2486+Q2486>0,"Sim","Não") -> Sim | X2486: =IF(F2486+L2486+R2486>0,"Sim","Não") -> Não | Y2486: =IF(G2486+M2486+S2486>0,"Sim","Não") -> Não
A2487: 261050 | B2487: =IFERROR(VLOOKUP(A2487,[1]Monitoramento_Base_somente_Said!$A:$J,5,FALSE),0) -> 365 | C2487: =IFERROR(VLOOKUP(A2487,[1]Monitoramento_Base_somente_Said!$A:$J,6,FALSE),0) -> 17010591 | D2487: =IFERROR(VLOOKUP(A2487,[1]Monitoramento_Base_somente_Said!$A:$J,7,FALSE),0) -> 565 | E2487: =IFERROR(VLOOKUP(A2487,[1]Monitoramento_Base_somente_Said!$A:$J,8,FALSE),0) -> 21492852 | F2487: =IFERROR(VLOOKUP(A2487,[1]Monitoramento_Base_somente_Said!$A:$J,9,FALSE),0) -> 0 | G2487: =IFERROR(VLOOKUP(A2487,[1]Monitoramento_Base_somente_Said!$A:$J,10,FALSE),0) -> 0 | H2487: =IFERROR(VLOOKUP(A2487,[2]Sheet1!$A:$I,4,FALSE),0) -> 0 | I2487: =IFERROR(VLOOKUP(A2487,[2]Sheet1!$A:$I,5,FALSE),0) -> 0 | J2487: =IFERROR(VLOOKUP(A2487,[2]Sheet1!$A:$I,6,FALSE),0) -> 0 | K2487: =IFERROR(VLOOKUP(A2487,[2]Sheet1!$A:$I,7,FALSE),0) -> 0 | L2487: =IFERROR(VLOOKUP(A2487,[2]Sheet1!$A:$I,8,FALSE),0) -> 0 | M2487: =IFERROR(VLOOKUP(A2487,[2]Sheet1!$A:$I,9,FALSE),0) -> 0 | N2487: =IFERROR(VLOOKUP(A2487,[3]Sheet1!$A:$G,2,FALSE),0) -> 0 | O2487: =IFERROR(VLOOKUP(A2487,[3]Sheet1!$A:$G,3,FALSE),0) -> 0 | P2487: =IFERROR(VLOOKUP(A2487,[3]Sheet1!$A:$G,4,FALSE),0) -> 0 | Q2487: =IFERROR(VLOOKUP(A2487,[3]Sheet1!$A:$G,5,FALSE),0) -> 0 | R2487: =IFERROR(VLOOKUP(A2487,[3]Sheet1!$A:$H,6,FALSE),0) -> 0 | S2487: =IFERROR(VLOOKUP(A2487,[3]Sheet1!$A:$I,7,FALSE),0) -> 0 | T2487: =IF(B2487+H2487+N2487>0,"Sim","Não") -> Sim | U2487: =IF(C2487+I2487+O2487>0,"Sim","Não") -> Sim | V2487: =IF(D2487+J2487+P2487>0,"Sim","Não") -> Sim | W2487: =IF(E2487+K2487+Q2487>0,"Sim","Não") -> Sim | X2487: =IF(F2487+L2487+R2487>0,"Sim","Não") -> Não | Y2487: =IF(G2487+M2487+S2487>0,"Sim","Não") -> Não
A2488: 261060 | B2488: =IFERROR(VLOOKUP(A2488,[1]Monitoramento_Base_somente_Said!$A:$J,5,FALSE),0) -> 132070 | C2488: =IFERROR(VLOOKUP(A2488,[1]Monitoramento_Base_somente_Said!$A:$J,6,FALSE),0) -> 155834795 | D2488: =IFERROR(VLOOKUP(A2488,[1]Monitoramento_Base_somente_Said!$A:$J,7,FALSE),0) -> 102656 | E2488: =IFERROR(VLOOKUP(A2488,[1]Monitoramento_Base_somente_Said!$A:$J,8,FALSE),0) -> 150272652 | F2488: =IFERROR(VLOOKUP(A2488,[1]Monitoramento_Base_somente_Said!$A:$J,9,FALSE),0) -> 0 | G2488: =IFERROR(VLOOKUP(A2488,[1]Monitoramento_Base_somente_Said!$A:$J,10,FALSE),0) -> 0 | H2488: =IFERROR(VLOOKUP(A2488,[2]Sheet1!$A:$I,4,FALSE),0) -> 0 | I2488: =IFERROR(VLOOKUP(A2488,[2]Sheet1!$A:$I,5,FALSE),0) -> 0 | J2488: =IFERROR(VLOOKUP(A2488,[2]Sheet1!$A:$I,6,FALSE),0) -> 0 | K2488: =IFERROR(VLOOKUP(A2488,[2]Sheet1!$A:$I,7,FALSE),0) -> 0 | L2488: =IFERROR(VLOOKUP(A2488,[2]Sheet1!$A:$I,8,FALSE),0) -> 0 | M2488: =IFERROR(VLOOKUP(A2488,[2]Sheet1!$A:$I,9,FALSE),0) -> 0 | N2488: =IFERROR(VLOOKUP(A2488,[3]Sheet1!$A:$G,2,FALSE),0) -> 0 | O2488: =IFERROR(VLOOKUP(A2488,[3]Sheet1!$A:$G,3,FALSE),0) -> 0 | P2488: =IFERROR(VLOOKUP(A2488,[3]Sheet1!$A:$G,4,FALSE),0) -> 0 | Q2488: =IFERROR(VLOOKUP(A2488,[3]Sheet1!$A:$G,5,FALSE),0) -> 0 | R2488: =IFERROR(VLOOKUP(A2488,[3]Sheet1!$A:$H,6,FALSE),0) -> 0 | S2488: =IFERROR(VLOOKUP(A2488,[3]Sheet1!$A:$I,7,FALSE),0) -> 0 | T2488: =IF(B2488+H2488+N2488>0,"Sim","Não") -> Sim | U2488: =IF(C2488+I2488+O2488>0,"Sim","Não") -> Sim | V2488: =IF(D2488+J2488+P2488>0,"Sim","Não") -> Sim | W2488: =IF(E2488+K2488+Q2488>0,"Sim","Não") -> Sim | X2488: =IF(F2488+L2488+R2488>0,"Sim","Não") -> Não | Y2488: =IF(G2488+M2488+S2488>0,"Sim","Não") -> Não
A2489: 261070 | B2489: 63925 | C2489: 2846768 | D2489: 115907 | E2489: 11583838 | F2489: =IFERROR(VLOOKUP(A2489,[1]Monitoramento_Base_somente_Said!$A:$J,9,FALSE),0) -> 0 | G2489: =IFERROR(VLOOKUP(A2489,[1]Monitoramento_Base_somente_Said!$A:$J,10,FALSE),0) -> 0 | H2489: =IFERROR(VLOOKUP(A2489,[2]Sheet1!$A:$I,4,FALSE),0) -> 0 | I2489: =IFERROR(VLOOKUP(A2489,[2]Sheet1!$A:$I,5,FALSE),0) -> 0 | J2489: =IFERROR(VLOOKUP(A2489,[2]Sheet1!$A:$I,6,FALSE),0) -> 0 | K2489: =IFERROR(VLOOKUP(A2489,[2]Sheet1!$A:$I,7,FALSE),0) -> 0 | L2489: =IFERROR(VLOOKUP(A2489,[2]Sheet1!$A:$I,8,FALSE),0) -> 0 | M2489: =IFERROR(VLOOKUP(A2489,[2]Sheet1!$A:$I,9,FALSE),0) -> 0 | N2489: =IFERROR(VLOOKUP(A2489,[3]Sheet1!$A:$G,2,FALSE),0) -> 0 | O2489: =IFERROR(VLOOKUP(A2489,[3]Sheet1!$A:$G,3,FALSE),0) -> 0 | P2489: =IFERROR(VLOOKUP(A2489,[3]Sheet1!$A:$G,4,FALSE),0) -> 0 | Q2489: 0 | R2489: =IFERROR(VLOOKUP(A2489,[3]Sheet1!$A:$H,6,FALSE),0) -> 0 | S2489: =IFERROR(VLOOKUP(A2489,[3]Sheet1!$A:$I,7,FALSE),0) -> 0 | T2489: =IF(B2489+H2489+N2489>0,"Sim","Não") -> Sim | U2489: =IF(C2489+I2489+O2489>0,"Sim","Não") -> Sim | V2489: =IF(D2489+J2489+P2489>0,"Sim","Não") -> Sim | W2489: =IF(E2489+K2489+Q2489>0,"Sim","Não") -> Sim | X2489: =IF(F2489+L2489+R2489>0,"Sim","Não") -> Não | Y2489: =IF(G2489+M2489+S2489>0,"Sim","Não") -> Não
A2490: 261080 | B2490: =IFERROR(VLOOKUP(A2490,[1]Monitoramento_Base_somente_Said!$A:$J,5,FALSE),0) -> 13050 | C2490: =IFERROR(VLOOKUP(A2490,[1]Monitoramento_Base_somente_Said!$A:$J,6,FALSE),0) -> 5746639 | D2490: =IFERROR(VLOOKUP(A2490,[1]Monitoramento_Base_somente_Said!$A:$J,7,FALSE),0) -> 40868 | E2490: =IFERROR(VLOOKUP(A2490,[1]Monitoramento_Base_somente_Said!$A:$J,8,FALSE),0) -> 5233687 | F2490: =IFERROR(VLOOKUP(A2490,[1]Monitoramento_Base_somente_Said!$A:$J,9,FALSE),0) -> 0 | G2490: =IFERROR(VLOOKUP(A2490,[1]Monitoramento_Base_somente_Said!$A:$J,10,FALSE),0) -> 0 | H2490: =IFERROR(VLOOKUP(A2490,[2]Sheet1!$A:$I,4,FALSE),0) -> 0 | I2490: =IFERROR(VLOOKUP(A2490,[2]Sheet1!$A:$I,5,FALSE),0) -> 0 | J2490: =IFERROR(VLOOKUP(A2490,[2]Sheet1!$A:$I,6,FALSE),0) -> 0 | K2490: =IFERROR(VLOOKUP(A2490,[2]Sheet1!$A:$I,7,FALSE),0) -> 0 | L2490: =IFERROR(VLOOKUP(A2490,[2]Sheet1!$A:$I,8,FALSE),0) -> 0 | M2490: =IFERROR(VLOOKUP(A2490,[2]Sheet1!$A:$I,9,FALSE),0) -> 0 | N2490: =IFERROR(VLOOKUP(A2490,[3]Sheet1!$A:$G,2,FALSE),0) -> 0 | O2490: =IFERROR(VLOOKUP(A2490,[3]Sheet1!$A:$G,3,FALSE),0) -> 0 | P2490: =IFERROR(VLOOKUP(A2490,[3]Sheet1!$A:$G,4,FALSE),0) -> 0 | Q2490: =IFERROR(VLOOKUP(A2490,[3]Sheet1!$A:$G,5,FALSE),0) -> 0 | R2490: =IFERROR(VLOOKUP(A2490,[3]Sheet1!$A:$H,6,FALSE),0) -> 0 | S2490: =IFERROR(VLOOKUP(A2490,[3]Sheet1!$A:$I,7,FALSE),0) -> 0 | T2490: =IF(B2490+H2490+N2490>0,"Sim","Não") -> Sim | U2490: =IF(C2490+I2490+O2490>0,"Sim","Não") -> Sim | V2490: =IF(D2490+J2490+P2490>0,"Sim","Não") -> Sim | W2490: =IF(E2490+K2490+Q2490>0,"Sim","Não") -> Sim | X2490: =IF(F2490+L2490+R2490>0,"Sim","Não") -> Não | Y2490: =IF(G2490+M2490+S2490>0,"Sim","Não") -> Não
A2491: 261090 | B2491: =IFERROR(VLOOKUP(A2491,[1]Monitoramento_Base_somente_Said!$A:$J,5,FALSE),0) -> 2572 | C2491: =IFERROR(VLOOKUP(A2491,[1]Monitoramento_Base_somente_Said!$A:$J,6,FALSE),0) -> 6656712 | D2491: =IFERROR(VLOOKUP(A2491,[1]Monitoramento_Base_somente_Said!$A:$J,7,FALSE),0) -> 2588 | E2491: =IFERROR(VLOOKUP(A2491,[1]Monitoramento_Base_somente_Said!$A:$J,8,FALSE),0) -> 6472188 | F2491: =IFERROR(VLOOKUP(A2491,[1]Monitoramento_Base_somente_Said!$A:$J,9,FALSE),0) -> 0 | G2491: =IFERROR(VLOOKUP(A2491,[1]Monitoramento_Base_somente_Said!$A:$J,10,FALSE),0) -> 0 | H2491: =IFERROR(VLOOKUP(A2491,[2]Sheet1!$A:$I,4,FALSE),0) -> 0 | I2491: =IFERROR(VLOOKUP(A2491,[2]Sheet1!$A:$I,5,FALSE),0) -> 0 | J2491: =IFERROR(VLOOKUP(A2491,[2]Sheet1!$A:$I,6,FALSE),0) -> 0 | K2491: =IFERROR(VLOOKUP(A2491,[2]Sheet1!$A:$I,7,FALSE),0) -> 0 | L2491: =IFERROR(VLOOKUP(A2491,[2]Sheet1!$A:$I,8,FALSE),0) -> 0 | M2491: =IFERROR(VLOOKUP(A2491,[2]Sheet1!$A:$I,9,FALSE),0) -> 0 | N2491: =IFERROR(VLOOKUP(A2491,[3]Sheet1!$A:$G,2,FALSE),0) -> 0 | O2491: =IFERROR(VLOOKUP(A2491,[3]Sheet1!$A:$G,3,FALSE),0) -> 0 | P2491: =IFERROR(VLOOKUP(A2491,[3]Sheet1!$A:$G,4,FALSE),0) -> 0 | Q2491: =IFERROR(VLOOKUP(A2491,[3]Sheet1!$A:$G,5,FALSE),0) -> 0 | R2491: =IFERROR(VLOOKUP(A2491,[3]Sheet1!$A:$H,6,FALSE),0) -> 0 | S2491: =IFERROR(VLOOKUP(A2491,[3]Sheet1!$A:$I,7,FALSE),0) -> 0 | T2491: =IF(B2491+H2491+N2491>0,"Sim","Não") -> Sim | U2491: =IF(C2491+I2491+O2491>0,"Sim","Não") -> Sim | V2491: =IF(D2491+J2491+P2491>0,"Sim","Não") -> Sim | W2491: =IF(E2491+K2491+Q2491>0,"Sim","Não") -> Sim | X2491: =IF(F2491+L2491+R2491>0,"Sim","Não") -> Não | Y2491: =IF(G2491+M2491+S2491>0,"Sim","Não") -> Não
A2492: 261100 | B2492: =IFERROR(VLOOKUP(A2492,[1]Monitoramento_Base_somente_Said!$A:$J,5,FALSE),0) -> 225504 | C2492: =IFERROR(VLOOKUP(A2492,[1]Monitoramento_Base_somente_Said!$A:$J,6,FALSE),0) -> 49582607 | D2492: =IFERROR(VLOOKUP(A2492,[1]Monitoramento_Base_somente_Said!$A:$J,7,FALSE),0) -> 238045 | E2492: =IFERROR(VLOOKUP(A2492,[1]Monitoramento_Base_somente_Said!$A:$J,8,FALSE),0) -> 46574700 | F2492: =IFERROR(VLOOKUP(A2492,[1]Monitoramento_Base_somente_Said!$A:$J,9,FALSE),0) -> 0 | G2492: =IFERROR(VLOOKUP(A2492,[1]Monitoramento_Base_somente_Said!$A:$J,10,FALSE),0) -> 0 | H2492: =IFERROR(VLOOKUP(A2492,[2]Sheet1!$A:$I,4,FALSE),0) -> 0 | I2492: =IFERROR(VLOOKUP(A2492,[2]Sheet1!$A:$I,5,FALSE),0) -> 0 | J2492: =IFERROR(VLOOKUP(A2492,[2]Sheet1!$A:$I,6,FALSE),0) -> 0 | K2492: =IFERROR(VLOOKUP(A2492,[2]Sheet1!$A:$I,7,FALSE),0) -> 0 | L2492: =IFERROR(VLOOKUP(A2492,[2]Sheet1!$A:$I,8,FALSE),0) -> 0 | M2492: =IFERROR(VLOOKUP(A2492,[2]Sheet1!$A:$I,9,FALSE),0) -> 0 | N2492: =IFERROR(VLOOKUP(A2492,[3]Sheet1!$A:$G,2,FALSE),0) -> 0 | O2492: =IFERROR(VLOOKUP(A2492,[3]Sheet1!$A:$G,3,FALSE),0) -> 0 | P2492: =IFERROR(VLOOKUP(A2492,[3]Sheet1!$A:$G,4,FALSE),0) -> 0 | Q2492: =IFERROR(VLOOKUP(A2492,[3]Sheet1!$A:$G,5,FALSE),0) -> 0 | R2492: =IFERROR(VLOOKUP(A2492,[3]Sheet1!$A:$H,6,FALSE),0) -> 0 | S2492: =IFERROR(VLOOKUP(A2492,[3]Sheet1!$A:$I,7,FALSE),0) -> 0 | T2492: =IF(B2492+H2492+N2492>0,"Sim","Não") -> Sim | U2492: =IF(C2492+I2492+O2492>0,"Sim","Não") -> Sim | V2492: =IF(D2492+J2492+P2492>0,"Sim","Não") -> Sim | W2492: =IF(E2492+K2492+Q2492>0,"Sim","Não") -> Sim | X2492: =IF(F2492+L2492+R2492>0,"Sim","Não") -> Não | Y2492: =IF(G2492+M2492+S2492>0,"Sim","Não") -> Não
A2493: 261120 | B2493: =IFERROR(VLOOKUP(A2493,[1]Monitoramento_Base_somente_Said!$A:$J,5,FALSE),0) -> 433710 | C2493: =IFERROR(VLOOKUP(A2493,[1]Monitoramento_Base_somente_Said!$A:$J,6,FALSE),0) -> 41458008 | D2493: =IFERROR(VLOOKUP(A2493,[1]Monitoramento_Base_somente_Said!$A:$J,7,FALSE),0) -> 194046 | E2493: =IFERROR(VLOOKUP(A2493,[1]Monitoramento_Base_somente_Said!$A:$J,8,FALSE),0) -> 40433936 | F2493: =IFERROR(VLOOKUP(A2493,[1]Monitoramento_Base_somente_Said!$A:$J,9,FALSE),0) -> 0 | G2493: =IFERROR(VLOOKUP(A2493,[1]Monitoramento_Base_somente_Said!$A:$J,10,FALSE),0) -> 0 | H2493: =IFERROR(VLOOKUP(A2493,[2]Sheet1!$A:$I,4,FALSE),0) -> 0 | I2493: =IFERROR(VLOOKUP(A2493,[2]Sheet1!$A:$I,5,FALSE),0) -> 0 | J2493: =IFERROR(VLOOKUP(A2493,[2]Sheet1!$A:$I,6,FALSE),0) -> 0 | K2493: =IFERROR(VLOOKUP(A2493,[2]Sheet1!$A:$I,7,FALSE),0) -> 0 | L2493: =IFERROR(VLOOKUP(A2493,[2]Sheet1!$A:$I,8,FALSE),0) -> 0 | M2493: =IFERROR(VLOOKUP(A2493,[2]Sheet1!$A:$I,9,FALSE),0) -> 0 | N2493: =IFERROR(VLOOKUP(A2493,[3]Sheet1!$A:$G,2,FALSE),0) -> 0 | O2493: =IFERROR(VLOOKUP(A2493,[3]Sheet1!$A:$G,3,FALSE),0) -> 0 | P2493: =IFERROR(VLOOKUP(A2493,[3]Sheet1!$A:$G,4,FALSE),0) -> 0 | Q2493: =IFERROR(VLOOKUP(A2493,[3]Sheet1!$A:$G,5,FALSE),0) -> 0 | R2493: =IFERROR(VLOOKUP(A2493,[3]Sheet1!$A:$H,6,FALSE),0) -> 0 | S2493: =IFERROR(VLOOKUP(A2493,[3]Sheet1!$A:$I,7,FALSE),0) -> 0 | T2493: =IF(B2493+H2493+N2493>0,"Sim","Não") -> Sim | U2493: =IF(C2493+I2493+O2493>0,"Sim","Não") -> Sim | V2493: =IF(D2493+J2493+P2493>0,"Sim","Não") -> Sim | W2493: =IF(E2493+K2493+Q2493>0,"Sim","Não") -> Sim | X2493: =IF(F2493+L2493+R2493>0,"Sim","Não") -> Não | Y2493: =IF(G2493+M2493+S2493>0,"Sim","Não") -> Não
A2494: 261130 | B2494: =IFERROR(VLOOKUP(A2494,[1]Monitoramento_Base_somente_Said!$A:$J,5,FALSE),0) -> 0 | C2494: =IFERROR(VLOOKUP(A2494,[1]Monitoramento_Base_somente_Said!$A:$J,6,FALSE),0) -> 0 | D2494: =IFERROR(VLOOKUP(A2494,[1]Monitoramento_Base_somente_Said!$A:$J,7,FALSE),0) -> 0 | E2494: =IFERROR(VLOOKUP(A2494,[1]Monitoramento_Base_somente_Said!$A:$J,8,FALSE),0) -> 0 | F2494: =IFERROR(VLOOKUP(A2494,[1]Monitoramento_Base_somente_Said!$A:$J,9,FALSE),0) -> 0 | G2494: =IFERROR(VLOOKUP(A2494,[1]Monitoramento_Base_somente_Said!$A:$J,10,FALSE),0) -> 0 | H2494: =IFERROR(VLOOKUP(A2494,[2]Sheet1!$A:$I,4,FALSE),0) -> 0 | I2494: =IFERROR(VLOOKUP(A2494,[2]Sheet1!$A:$I,5,FALSE),0) -> 0 | J2494: =IFERROR(VLOOKUP(A2494,[2]Sheet1!$A:$I,6,FALSE),0) -> 0 | K2494: =IFERROR(VLOOKUP(A2494,[2]Sheet1!$A:$I,7,FALSE),0) -> 0 | L2494: =IFERROR(VLOOKUP(A2494,[2]Sheet1!$A:$I,8,FALSE),0) -> 0 | M2494: =IFERROR(VLOOKUP(A2494,[2]Sheet1!$A:$I,9,FALSE),0) -> 0 | N2494: =IFERROR(VLOOKUP(A2494,[3]Sheet1!$A:$G,2,FALSE),0) -> 15210 | O2494: =IFERROR(VLOOKUP(A2494,[3]Sheet1!$A:$G,3,FALSE),0) -> 3218210 | P2494: =IFERROR(VLOOKUP(A2494,[3]Sheet1!$A:$G,4,FALSE),0) -> 47330 | Q2494: =IFERROR(VLOOKUP(A2494,[3]Sheet1!$A:$G,5,FALSE),0) -> 3313973 | R2494: =IFERROR(VLOOKUP(A2494,[3]Sheet1!$A:$H,6,FALSE),0) -> 0 | S2494: =IFERROR(VLOOKUP(A2494,[3]Sheet1!$A:$I,7,FALSE),0) -> 0 | T2494: =IF(B2494+H2494+N2494>0,"Sim","Não") -> Sim | U2494: =IF(C2494+I2494+O2494>0,"Sim","Não") -> Sim | V2494: =IF(D2494+J2494+P2494>0,"Sim","Não") -> Sim | W2494: =IF(E2494+K2494+Q2494>0,"Sim","Não") -> Sim | X2494: =IF(F2494+L2494+R2494>0,"Sim","Não") -> Não | Y2494: =IF(G2494+M2494+S2494>0,"Sim","Não") -> Não
A2495: 261140 | B2495: =IFERROR(VLOOKUP(A2495,[1]Monitoramento_Base_somente_Said!$A:$J,5,FALSE),0) -> 182309 | C2495: =IFERROR(VLOOKUP(A2495,[1]Monitoramento_Base_somente_Said!$A:$J,6,FALSE),0) -> 8946161 | D2495: =IFERROR(VLOOKUP(A2495,[1]Monitoramento_Base_somente_Said!$A:$J,7,FALSE),0) -> 500605 | E2495: =IFERROR(VLOOKUP(A2495,[1]Monitoramento_Base_somente_Said!$A:$J,8,FALSE),0) -> 4193776 | F2495: =IFERROR(VLOOKUP(A2495,[1]Monitoramento_Base_somente_Said!$A:$J,9,FALSE),0) -> 0 | G2495: =IFERROR(VLOOKUP(A2495,[1]Monitoramento_Base_somente_Said!$A:$J,10,FALSE),0) -> 0 | H2495: =IFERROR(VLOOKUP(A2495,[2]Sheet1!$A:$I,4,FALSE),0) -> 0 | I2495: =IFERROR(VLOOKUP(A2495,[2]Sheet1!$A:$I,5,FALSE),0) -> 0 | J2495: =IFERROR(VLOOKUP(A2495,[2]Sheet1!$A:$I,6,FALSE),0) -> 0 | K2495: =IFERROR(VLOOKUP(A2495,[2]Sheet1!$A:$I,7,FALSE),0) -> 0 | L2495: =IFERROR(VLOOKUP(A2495,[2]Sheet1!$A:$I,8,FALSE),0) -> 0 | M2495: =IFERROR(VLOOKUP(A2495,[2]Sheet1!$A:$I,9,FALSE),0) -> 0 | N2495: =IFERROR(VLOOKUP(A2495,[3]Sheet1!$A:$G,2,FALSE),0) -> 0 | O2495: =IFERROR(VLOOKUP(A2495,[3]Sheet1!$A:$G,3,FALSE),0) -> 0 | P2495: =IFERROR(VLOOKUP(A2495,[3]Sheet1!$A:$G,4,FALSE),0) -> 0 | Q2495: =IFERROR(VLOOKUP(A2495,[3]Sheet1!$A:$G,5,FALSE),0) -> 0 | R2495: =IFERROR(VLOOKUP(A2495,[3]Sheet1!$A:$H,6,FALSE),0) -> 0 | S2495: =IFERROR(VLOOKUP(A2495,[3]Sheet1!$A:$I,7,FALSE),0) -> 0 | T2495: =IF(B2495+H2495+N2495>0,"Sim","Não") -> Sim | U2495: =IF(C2495+I2495+O2495>0,"Sim","Não") -> Sim | V2495: =IF(D2495+J2495+P2495>0,"Sim","Não") -> Sim | W2495: =IF(E2495+K2495+Q2495>0,"Sim","Não") -> Sim | X2495: =IF(F2495+L2495+R2495>0,"Sim","Não") -> Não | Y2495: =IF(G2495+M2495+S2495>0,"Sim","Não") -> Não
A2496: 261150 | B2496: =IFERROR(VLOOKUP(A2496,[1]Monitoramento_Base_somente_Said!$A:$J,5,FALSE),0) -> 20353 | C2496: =IFERROR(VLOOKUP(A2496,[1]Monitoramento_Base_somente_Said!$A:$J,6,FALSE),0) -> 9142823 | D2496: =IFERROR(VLOOKUP(A2496,[1]Monitoramento_Base_somente_Said!$A:$J,7,FALSE),0) -> 11590 | E2496: =IFERROR(VLOOKUP(A2496,[1]Monitoramento_Base_somente_Said!$A:$J,8,FALSE),0) -> 8446050 | F2496: =IFERROR(VLOOKUP(A2496,[1]Monitoramento_Base_somente_Said!$A:$J,9,FALSE),0) -> 0 | G2496: =IFERROR(VLOOKUP(A2496,[1]Monitoramento_Base_somente_Said!$A:$J,10,FALSE),0) -> 0 | H2496: =IFERROR(VLOOKUP(A2496,[2]Sheet1!$A:$I,4,FALSE),0) -> 0 | I2496: =IFERROR(VLOOKUP(A2496,[2]Sheet1!$A:$I,5,FALSE),0) -> 0 | J2496: =IFERROR(VLOOKUP(A2496,[2]Sheet1!$A:$I,6,FALSE),0) -> 0 | K2496: =IFERROR(VLOOKUP(A2496,[2]Sheet1!$A:$I,7,FALSE),0) -> 0 | L2496: =IFERROR(VLOOKUP(A2496,[2]Sheet1!$A:$I,8,FALSE),0) -> 0 | M2496: =IFERROR(VLOOKUP(A2496,[2]Sheet1!$A:$I,9,FALSE),0) -> 0 | N2496: =IFERROR(VLOOKUP(A2496,[3]Sheet1!$A:$G,2,FALSE),0) -> 0 | O2496: =IFERROR(VLOOKUP(A2496,[3]Sheet1!$A:$G,3,FALSE),0) -> 0 | P2496: =IFERROR(VLOOKUP(A2496,[3]Sheet1!$A:$G,4,FALSE),0) -> 0 | Q2496: =IFERROR(VLOOKUP(A2496,[3]Sheet1!$A:$G,5,FALSE),0) -> 0 | R2496: =IFERROR(VLOOKUP(A2496,[3]Sheet1!$A:$H,6,FALSE),0) -> 0 | S2496: =IFERROR(VLOOKUP(A2496,[3]Sheet1!$A:$I,7,FALSE),0) -> 0 | T2496: =IF(B2496+H2496+N2496>0,"Sim","Não") -> Sim | U2496: =IF(C2496+I2496+O2496>0,"Sim","Não") -> Sim | V2496: =IF(D2496+J2496+P2496>0,"Sim","Não") -> Sim | W2496: =IF(E2496+K2496+Q2496>0,"Sim","Não") -> Sim | X2496: =IF(F2496+L2496+R2496>0,"Sim","Não") -> Não | Y2496: =IF(G2496+M2496+S2496>0,"Sim","Não") -> Não
A2497: 261153 | B2497: =IFERROR(VLOOKUP(A2497,[1]Monitoramento_Base_somente_Said!$A:$J,5,FALSE),0) -> 120734 | C2497: =IFERROR(VLOOKUP(A2497,[1]Monitoramento_Base_somente_Said!$A:$J,6,FALSE),0) -> 53983783 | D2497: =IFERROR(VLOOKUP(A2497,[1]Monitoramento_Base_somente_Said!$A:$J,7,FALSE),0) -> 296446 | E2497: =IFERROR(VLOOKUP(A2497,[1]Monitoramento_Base_somente_Said!$A:$J,8,FALSE),0) -> 52344245 | F2497: =IFERROR(VLOOKUP(A2497,[1]Monitoramento_Base_somente_Said!$A:$J,9,FALSE),0) -> 0 | G2497: =IFERROR(VLOOKUP(A2497,[1]Monitoramento_Base_somente_Said!$A:$J,10,FALSE),0) -> 0 | H2497: =IFERROR(VLOOKUP(A2497,[2]Sheet1!$A:$I,4,FALSE),0) -> 0 | I2497: =IFERROR(VLOOKUP(A2497,[2]Sheet1!$A:$I,5,FALSE),0) -> 0 | J2497: =IFERROR(VLOOKUP(A2497,[2]Sheet1!$A:$I,6,FALSE),0) -> 0 | K2497: =IFERROR(VLOOKUP(A2497,[2]Sheet1!$A:$I,7,FALSE),0) -> 0 | L2497: =IFERROR(VLOOKUP(A2497,[2]Sheet1!$A:$I,8,FALSE),0) -> 0 | M2497: =IFERROR(VLOOKUP(A2497,[2]Sheet1!$A:$I,9,FALSE),0) -> 0 | N2497: =IFERROR(VLOOKUP(A2497,[3]Sheet1!$A:$G,2,FALSE),0) -> 0 | O2497: =IFERROR(VLOOKUP(A2497,[3]Sheet1!$A:$G,3,FALSE),0) -> 0 | P2497: =IFERROR(VLOOKUP(A2497,[3]Sheet1!$A:$G,4,FALSE),0) -> 0 | Q2497: =IFERROR(VLOOKUP(A2497,[3]Sheet1!$A:$G,5,FALSE),0) -> 0 | R2497: =IFERROR(VLOOKUP(A2497,[3]Sheet1!$A:$H,6,FALSE),0) -> 0 | S2497: =IFERROR(VLOOKUP(A2497,[3]Sheet1!$A:$I,7,FALSE),0) -> 0 | T2497: =IF(B2497+H2497+N2497>0,"Sim","Não") -> Sim | U2497: =IF(C2497+I2497+O2497>0,"Sim","Não") -> Sim | V2497: =IF(D2497+J2497+P2497>0,"Sim","Não") -> Sim | W2497: =IF(E2497+K2497+Q2497>0,"Sim","Não") -> Sim | X2497: =IF(F2497+L2497+R2497>0,"Sim","Não") -> Não | Y2497: =IF(G2497+M2497+S2497>0,"Sim","Não") -> Não
